Workbook
Name ______new1: #REF!
Name _____new1: #REF!
Name ___new1: #REF!
Name __new1: #REF!
Name _2004: #REF!
Name _2005: #REF!
Name _2006: #REF!
Name _2007: #REF!
Name _2008: #REF!
Name _2009: #REF!
Name _2010: #REF!
Name _2011: #REF!
Name _2012: #REF!
Name _2013: #REF!
Name _2013_: #REF!
Name _2014: #REF!
Name _2015: #REF!
Name _2016: #REF!
Name _2017: #REF!
Name _2018: #REF!
Name _2020: #REF!
Name _3000: #REF!
Name _3010: #REF!
Name _3019: #REF!
Name _3310: #REF!
Name _4320: #REF!
Name _4355: #REF!
Name _4405: #REF!
Name _4410: #REF!
Name _4445: #REF!
Name _4450: #REF!
Name _4452: #REF!
Name _4453: #REF!
Name _4480: #REF!
Name _4485: #REF!
Name _4496: #REF!
Name _4505: #REF!
Name _4555: #REF!
Name _4560: #REF!
Name _4710: #REF!
Name _4715: #REF!
Name _4830: #REF!
Name _4848: #REF!
Name _ADM2000: #REF!
Name _ADM2001: #REF!
Name _Bud02: #REF!
Name _Bud03: #REF!
Name _CAM96: #REF!
Name _CAM97: #REF!
Name _CAM98: #REF!
Name _DPU95: #REF!
Name _end1: IF([0]!Loan_Amount*[0]!Interest_Rate*[0]!Loan_Years*[0]!Loan_Start>0,1,0)
Name _EPU01: #REF!
Name _EPU02: #REF!
Name _EPU03: #REF!
Name _EPU04: #REF!
Name _EPU96: #REF!
Name _EPU97: #REF!
Name _EPU98: #REF!
Name _EPU99: #REF!

Sheet Pro Forma
B3: Base Assumptions | I3: Yr | Z3: 0 | AA3: 1 | AB3: 1 | AC3: 1 | AD3: 1 | AE3: 1 | AF3: 1 | AG3: 1 | AH3: 1 | AI3: 1 | AJ3: 1 | AK3: 1 | AL3: 1 | AM3: =AA3+1 | AN3: =AB3+1 | AO3: =AC3+1 | AP3: =AD3+1 | AQ3: =AE3+1 | AR3: =AF3+1 | AS3: =AG3+1 | AT3: =AH3+1 | ... FB3: =EP3+1
B4: Property Name: | C4: =Inputs!C81 | I4: Mo | Z4: 0 | AA4: =Z4+1 | AB4: =AA4+1 | AC4: =AB4+1 | AD4: =AC4+1 | AE4: =AD4+1 | AF4: =AE4+1 | AG4: =AF4+1 | AH4: =AG4+1 | ... FB4: =FA4+1
B5: Address: | C5: =Inputs!C82 | I5: Calendar Year | Z5: =YEAR(Z6) | AA5: =YEAR(AA6) | AB5: =YEAR(AB6) | AC5: =YEAR(AC6) | AD5: =YEAR(AD6) | AE5: =YEAR(AE6) | AF5: =YEAR(AF6) | AG5: =YEAR(AG6) | ... FB5: =YEAR(FB6)
B6: Returns Metrics | F6: Aequitas (LP) | G6: GP (Sponsor) | I6: Property Cash Flows | L6: Total | N6: Annual Cash Flow (Operating Year) | Z6: =D15 | AA6: =EOMONTH(Z6,0) | AB6: =EOMONTH(AA6,1) | AC6: =EOMONTH(AB6,1) | AD6: =EOMONTH(AC6,1) | AE6: =EOMONTH(AD6,1) | AF6: =EOMONTH(AE6,1) | AG6: =EOMONTH(AF6,1) | AH6: =EOMONTH(AG6,1) | AI6: =EOMONTH(AH6,1) | ... FB6: =EOMONTH(FA6,1)
B7: Deal-Level Return | C7: Unlevered | D7: Levered | E7: Partnership-Level | F7: =Inputs!C86 | G7: =1-F7 | I7: Pro Forma | N7: 0 | O7: =N7+1 | P7: =O7+1 | Q7: =P7+1 | R7: =Q7+1 | S7: =R7+1 | T7: =S7+1 | U7: =T7+1 | V7: =U7+1 | ... X7: =W7+1
B8: Net Profit | C8: =L98 | D8: =L115 | E8: Net Profit | F8: =L141 | G8: =L144 | I8: Growth Assumptions
B9: Peak Equity | C9: =L99 | D9: =L116 | E9: Peak Equity | F9: =-SUMIF(Z141:FB141,"<0",Z141:FB141) | G9: =-SUMIF(Z144:FB144,"<0",Z144:FB144) | I9: =B90 | N9: =SUMIF($Z$3:$FB$3,N$7,$Z9:$FB9) | O9: =SUMIF($Z$3:$FB$3,O$7,$Z9:$FB9) | P9: =SUMIF($Z$3:$FB$3,P$7,$Z9:$FB9) | Q9: =SUMIF($Z$3:$FB$3,Q$7,$Z9:$FB9) | R9: =SUMIF($Z$3:$FB$3,R$7,$Z9:$FB9) | S9: =SUMIF($Z$3:$FB$3,S$7,$Z9:$FB9) | T9: =SUMIF($Z$3:$FB$3,T$7,$Z9:$FB9) | U9: =SUMIF($Z$3:$FB$3,U$7,$Z9:$FB9) | ... X9: =SUMIF($Z$3:$FB$3,X$7,$Z9:$FB9) | Z9: 0 | AA9: =IFERROR(INDEX($C90:$G90,MATCH(YEAR(AA$6),$C$89:$G$89,0))/12,Z9) | AB9: =IFERROR(INDEX($C90:$G90,MATCH(YEAR(AB$6),$C$89:$G$89,0))/12,AA9) | AC9: =IFERROR(INDEX($C90:$G90,MATCH(YEAR(AC$6),$C$89:$G$89,0))/12,AB9) | AD9: =IFERROR(INDEX($C90:$G90,MATCH(YEAR(AD$6),$C$89:$G$89,0))/12,AC9) | AE9: =IFERROR(INDEX($C90:$G90,MATCH(YEAR(AE$6),$C$89:$G$89,0))/12,AD9) | AF9: =IFERROR(INDEX($C90:$G90,MATCH(YEAR(AF$6),$C$89:$G$89,0))/12,AE9) | AG9: =IFERROR(INDEX($C90:$G90,MATCH(YEAR(AG$6),$C$89:$G$89,0))/12,AF9) | AH9: =IFERROR(INDEX($C90:$G90,MATCH(YEAR(AH$6),$C$89:$G$89,0))/12,AG9) | ... FB9: =IFERROR(INDEX($C90:$G90,MATCH(YEAR(FB$6),$C$89:$G$89,0))/12,FA9)
B10: IRR | C10: =L100 | D10: =L117 | E10: IRR | F10: =L142 | G10: =L145 | I10: Compounded Rate | Z10: 1 | AA10: =Z10*(1+AA9) | AB10: =AA10*(1+AB9) | AC10: =AB10*(1+AC9) | AD10: =AC10*(1+AD9) | AE10: =AD10*(1+AE9) | AF10: =AE10*(1+AF9) | AG10: =AF10*(1+AG9) | AH10: =AG10*(1+AH9) | ... FB10: =FA10*(1+FB9)
B11: Equity Multiple | C11: =L101 | D11: =L118 | E11: Equity Multiple | F11: =L143 | G11: =L146 | I11: =B91 | N11: =SUMIF($Z$3:$FB$3,N$7,$Z11:$FB11) | O11: =SUMIF($Z$3:$FB$3,O$7,$Z11:$FB11) | P11: =SUMIF($Z$3:$FB$3,P$7,$Z11:$FB11) | Q11: =SUMIF($Z$3:$FB$3,Q$7,$Z11:$FB11) | R11: =SUMIF($Z$3:$FB$3,R$7,$Z11:$FB11) | S11: =SUMIF($Z$3:$FB$3,S$7,$Z11:$FB11) | T11: =SUMIF($Z$3:$FB$3,T$7,$Z11:$FB11) | U11: =SUMIF($Z$3:$FB$3,U$7,$Z11:$FB11) | ... X11: =SUMIF($Z$3:$FB$3,X$7,$Z11:$FB11) | Z11: 0 | AA11: =IFERROR(INDEX($C91:$G91,MATCH(YEAR(AA$6),$C$89:$G$89,0))/12,Z11) | AB11: =IFERROR(INDEX($C91:$G91,MATCH(YEAR(AB$6),$C$89:$G$89,0))/12,AA11) | AC11: =IFERROR(INDEX($C91:$G91,MATCH(YEAR(AC$6),$C$89:$G$89,0))/12,AB11) | AD11: =IFERROR(INDEX($C91:$G91,MATCH(YEAR(AD$6),$C$89:$G$89,0))/12,AC11) | AE11: =IFERROR(INDEX($C91:$G91,MATCH(YEAR(AE$6),$C$89:$G$89,0))/12,AD11) | AF11: =IFERROR(INDEX($C91:$G91,MATCH(YEAR(AF$6),$C$89:$G$89,0))/12,AE11) | AG11: =IFERROR(INDEX($C91:$G91,MATCH(YEAR(AG$6),$C$89:$G$89,0))/12,AF11) | AH11: =IFERROR(INDEX($C91:$G91,MATCH(YEAR(AH$6),$C$89:$G$89,0))/12,AG11) | ... FB11: =IFERROR(INDEX($C91:$G91,MATCH(YEAR(FB$6),$C$89:$G$89,0))/12,FA11)
I12: Compounded Rate | Z12: 1 | AA12: =Z12*(1+AA11) | AB12: =AA12*(1+AB11) | AC12: =AB12*(1+AC11) | AD12: =AC12*(1+AD11) | AE12: =AD12*(1+AE11) | AF12: =AE12*(1+AF11) | AG12: =AF12*(1+AG11) | AH12: =AG12*(1+AH11) | ... FB12: =FA12*(1+FB11)
B13: Timeline | I13: =B92 | N13: =SUMIF($Z$3:$FB$3,N$7,$Z13:$FB13) | O13: =SUMIF($Z$3:$FB$3,O$7,$Z13:$FB13) | P13: =SUMIF($Z$3:$FB$3,P$7,$Z13:$FB13) | Q13: =SUMIF($Z$3:$FB$3,Q$7,$Z13:$FB13) | R13: =SUMIF($Z$3:$FB$3,R$7,$Z13:$FB13) | S13: =SUMIF($Z$3:$FB$3,S$7,$Z13:$FB13) | T13: =SUMIF($Z$3:$FB$3,T$7,$Z13:$FB13) | U13: =SUMIF($Z$3:$FB$3,U$7,$Z13:$FB13) | ... X13: =SUMIF($Z$3:$FB$3,X$7,$Z13:$FB13) | Z13: 0 | AA13: =IFERROR(INDEX($C92:$G92,MATCH(YEAR(AA$6),$C$89:$G$89,0))/12,Z13) | AB13: =IFERROR(INDEX($C92:$G92,MATCH(YEAR(AB$6),$C$89:$G$89,0))/12,AA13) | AC13: =IFERROR(INDEX($C92:$G92,MATCH(YEAR(AC$6),$C$89:$G$89,0))/12,AB13) | AD13: =IFERROR(INDEX($C92:$G92,MATCH(YEAR(AD$6),$C$89:$G$89,0))/12,AC13) | AE13: =IFERROR(INDEX($C92:$G92,MATCH(YEAR(AE$6),$C$89:$G$89,0))/12,AD13) | AF13: =IFERROR(INDEX($C92:$G92,MATCH(YEAR(AF$6),$C$89:$G$89,0))/12,AE13) | AG13: =IFERROR(INDEX($C92:$G92,MATCH(YEAR(AG$6),$C$89:$G$89,0))/12,AF13) | AH13: =IFERROR(INDEX($C92:$G92,MATCH(YEAR(AH$6),$C$89:$G$89,0))/12,AG13) | ... FB13: =IFERROR(INDEX($C92:$G92,MATCH(YEAR(FB$6),$C$89:$G$89,0))/12,FA13)
C14: BOP Mo | D14: BOP Date | E14: Duration | F14: EOP Date | G14: EOP Mo | I14: Compounded Rate | Z14: 1 | AA14: =Z14*(1+AA13) | AB14: =AA14*(1+AB13) | AC14: =AB14*(1+AC13) | AD14: =AC14*(1+AD13) | AE14: =AD14*(1+AE13) | AF14: =AE14*(1+AF13) | AG14: =AF14*(1+AG13) | AH14: =AG14*(1+AH13) | ... FB14: =FA14*(1+FB13)
B15: Acquisition Date | C15: 0 | D15: =Inputs!C5 | E15: =Inputs!C6 | F15: =EOMONTH(D15,E15) | G15: =INDEX($Z$4:$FB$4,MATCH(F15,$Z$6:$FB$6,0)) | I15: =B93 | N15: =SUMIF($Z$3:$FB$3,N$7,$Z15:$FB15) | O15: =SUMIF($Z$3:$FB$3,O$7,$Z15:$FB15) | P15: =SUMIF($Z$3:$FB$3,P$7,$Z15:$FB15) | Q15: =SUMIF($Z$3:$FB$3,Q$7,$Z15:$FB15) | R15: =SUMIF($Z$3:$FB$3,R$7,$Z15:$FB15) | S15: =SUMIF($Z$3:$FB$3,S$7,$Z15:$FB15) | T15: =SUMIF($Z$3:$FB$3,T$7,$Z15:$FB15) | U15: =SUMIF($Z$3:$FB$3,U$7,$Z15:$FB15) | ... X15: =SUMIF($Z$3:$FB$3,X$7,$Z15:$FB15) | Z15: 0 | AA15: =IFERROR(INDEX($C93:$G93,MATCH(YEAR(AA$6),$C$89:$G$89,0))/12,Z15) | AB15: =IFERROR(INDEX($C93:$G93,MATCH(YEAR(AB$6),$C$89:$G$89,0))/12,AA15) | AC15: =IFERROR(INDEX($C93:$G93,MATCH(YEAR(AC$6),$C$89:$G$89,0))/12,AB15) | AD15: =IFERROR(INDEX($C93:$G93,MATCH(YEAR(AD$6),$C$89:$G$89,0))/12,AC15) | AE15: =IFERROR(INDEX($C93:$G93,MATCH(YEAR(AE$6),$C$89:$G$89,0))/12,AD15) | AF15: =IFERROR(INDEX($C93:$G93,MATCH(YEAR(AF$6),$C$89:$G$89,0))/12,AE15) | AG15: =IFERROR(INDEX($C93:$G93,MATCH(YEAR(AG$6),$C$89:$G$89,0))/12,AF15) | AH15: =IFERROR(INDEX($C93:$G93,MATCH(YEAR(AH$6),$C$89:$G$89,0))/12,AG15) | ... FB15: =IFERROR(INDEX($C93:$G93,MATCH(YEAR(FB$6),$C$89:$G$89,0))/12,FA15)
B16: Hold Period | C16: =INDEX($Z$4:$FB$4,MATCH(D16,$Z$6:$FB$6,0)) | D16: =EOMONTH(F15,0) | E16: =Inputs!C7 | F16: =EOMONTH(D16,E16-1) | G16: =INDEX($Z$4:$FB$4,MATCH(F16,$Z$6:$FB$6,0)) | I16: Compounded Rate | Z16: 1 | AA16: =Z16*(1+AA15) | AB16: =AA16*(1+AB15) | AC16: =AB16*(1+AC15) | AD16: =AC16*(1+AD15) | AE16: =AD16*(1+AE15) | AF16: =AE16*(1+AF15) | AG16: =AF16*(1+AG15) | AH16: =AG16*(1+AH15) | ... FB16: =FA16*(1+FB15)
B17: Refinance | C17: =INDEX($Z$4:$FB$4,MATCH(D17,$Z$6:$FB$6,0)) | D17: =EOMONTH(F16,0) | E17: 1 | F17: =EOMONTH(D17,E17-1) | G17: =INDEX($Z$4:$FB$4,MATCH(F17,$Z$6:$FB$6,0))
B18: =Inputs!C83 | C18: =INDEX($Z$4:$FB$4,MATCH(D18,$Z$6:$FB$6,0)) | D18: =EOMONTH(F17,0) | E18: =G18-C18 | F18: =EOMONTH(D15,B18*12-1) | G18: =INDEX($Z$4:$FB$4,MATCH(F18,$Z$6:$FB$6,0)) | I18: Rent Analysis
I19: Potential Gross MR Rent/Unit | Z19: =D75 | AA19: =Z19*(1+AA9) | AB19: =AA19*(1+AB9) | AC19: =AB19*(1+AC9) | AD19: =AC19*(1+AD9) | AE19: =AD19*(1+AE9) | AF19: =AE19*(1+AF9) | AG19: =AF19*(1+AG9) | AH19: =AG19*(1+AH9) | ... FB19: =FA19*(1+FB9)
B20: Valuation Analysis
B21: Entry Valuation | C21: Asking/Listing Price | D21: Aequitas Valuation | E21: Residual Analysis | F21: Refinance | G21: Exit | I21: Gross Potential Rent
B22: NOI (T-12) | C22: =Inputs!C8 | D22: =C22 | E22: NOI (T-12) | F22: =INDEX($Z$83:$FB$83,MATCH(C17,$Z$4:$FB$4,0)) | G22: =INDEX($Z$83:$FB$83,MATCH(G18,$Z$4:$FB$4,0)) | I22: Gross Potential Revenue | L22: =SUMIF($Z$4:$FB$4,"<="&$G$18,$Z22:$FB22) | N22: =SUMIF($Z$3:$FB$3,N$7,$Z22:$FB22) | O22: =SUMIF($Z$3:$FB$3,O$7,$Z22:$FB22) | P22: =SUMIF($Z$3:$FB$3,P$7,$Z22:$FB22) | Q22: =SUMIF($Z$3:$FB$3,Q$7,$Z22:$FB22) | R22: =SUMIF($Z$3:$FB$3,R$7,$Z22:$FB22) | S22: =SUMIF($Z$3:$FB$3,S$7,$Z22:$FB22) | T22: =SUMIF($Z$3:$FB$3,T$7,$Z22:$FB22) | U22: =SUMIF($Z$3:$FB$3,U$7,$Z22:$FB22) | ... X22: =SUMIF($Z$3:$FB$3,X$7,$Z22:$FB22) | Z22: 0 | AA22: =AA19*$C$75 | AB22: =AB19*$C$75 | AC22: =AC19*$C$75 | AD22: =AD19*$C$75 | AE22: =AE19*$C$75 | AF22: =AF19*$C$75 | AG22: =AG19*$C$75 | AH22: =AH19*$C$75 | ... FB22: =FB19*$C$75
B23: Cap Rate | C23: =C22/C24 | D23: =Inputs!C9 | E23: Cap Rate | F23: =C122 | G23: =F23 | I23: Loss-to-Lease | L23: =SUMIF($Z$4:$FB$4,"<="&$G$18,$Z23:$FB23) | N23: =SUMIF($Z$3:$FB$3,N$7,$Z23:$FB23) | O23: =SUMIF($Z$3:$FB$3,O$7,$Z23:$FB23) | P23: =SUMIF($Z$3:$FB$3,P$7,$Z23:$FB23) | Q23: =SUMIF($Z$3:$FB$3,Q$7,$Z23:$FB23) | R23: =SUMIF($Z$3:$FB$3,R$7,$Z23:$FB23) | S23: =SUMIF($Z$3:$FB$3,S$7,$Z23:$FB23) | T23: =SUMIF($Z$3:$FB$3,T$7,$Z23:$FB23) | U23: =SUMIF($Z$3:$FB$3,U$7,$Z23:$FB23) | ... X23: =SUMIF($Z$3:$FB$3,X$7,$Z23:$FB23) | Z23: 0 | AA23: =AA22*-IFERROR(INDEX($C$84:$G$84,MATCH(YEAR(AA6),$C$83:$G$83,0)),$G$84) | AB23: =AB22*-IFERROR(INDEX($C$84:$G$84,MATCH(YEAR(AB6),$C$83:$G$83,0)),$G$84) | AC23: =AC22*-IFERROR(INDEX($C$84:$G$84,MATCH(YEAR(AC6),$C$83:$G$83,0)),$G$84) | AD23: =AD22*-IFERROR(INDEX($C$84:$G$84,MATCH(YEAR(AD6),$C$83:$G$83,0)),$G$84) | AE23: =AE22*-IFERROR(INDEX($C$84:$G$84,MATCH(YEAR(AE6),$C$83:$G$83,0)),$G$84) | AF23: =AF22*-IFERROR(INDEX($C$84:$G$84,MATCH(YEAR(AF6),$C$83:$G$83,0)),$G$84) | AG23: =AG22*-IFERROR(INDEX($C$84:$G$84,MATCH(YEAR(AG6),$C$83:$G$83,0)),$G$84) | AH23: =AH22*-IFERROR(INDEX($C$84:$G$84,MATCH(YEAR(AH6),$C$83:$G$83,0)),$G$84) | ... FB23: =FB22*-IFERROR(INDEX($C$84:$G$84,MATCH(YEAR(FB6),$C$83:$G$83,0)),$G$84)
B24: Gross Value | C24: =Inputs!C84 | D24: =D22/D23 | E24: Gross Value | F24: =F22/F23 | G24: =G22/G23 | I24: Gross Potential Rent | L24: =SUMIF($Z$4:$FB$4,"<="&$G$18,$Z24:$FB24) | N24: =SUMIF($Z$3:$FB$3,N$7,$Z24:$FB24) | O24: =SUMIF($Z$3:$FB$3,O$7,$Z24:$FB24) | P24: =SUMIF($Z$3:$FB$3,P$7,$Z24:$FB24) | Q24: =SUMIF($Z$3:$FB$3,Q$7,$Z24:$FB24) | R24: =SUMIF($Z$3:$FB$3,R$7,$Z24:$FB24) | S24: =SUMIF($Z$3:$FB$3,S$7,$Z24:$FB24) | T24: =SUMIF($Z$3:$FB$3,T$7,$Z24:$FB24) | U24: =SUMIF($Z$3:$FB$3,U$7,$Z24:$FB24) | ... X24: =SUMIF($Z$3:$FB$3,X$7,$Z24:$FB24) | Z24: 0 | AA24: =SUM(AA22:AA23) | AB24: =SUM(AB22:AB23) | AC24: =SUM(AC22:AC23) | AD24: =SUM(AD22:AD23) | AE24: =SUM(AE22:AE23) | AF24: =SUM(AF22:AF23) | AG24: =SUM(AG22:AG23) | AH24: =SUM(AH22:AH23) | ... FB24: =SUM(FB22:FB23)
B25: $/Unit | C25: =C24/$C$75 | D25: =D24/$C$75 | E25: $/Unit | F25: =F24/$C$75 | G25: =G24/$C$75
C26: Delta | D26: =D24-C24 | E26: =Inputs!C10 | F26: =-$E26*F24 | G26: =-$E26*G24 | I26: Other Income
C27: $/Unit | D27: =D25-C25 | E27: Net Sales Proceeds | F27: =SUM(F24,F26) | G27: =SUM(G24,G26) | I27: RUBS | J27: =D78 | L27: =SUMIF($Z$4:$FB$4,"<="&$G$18,$Z27:$FB27) | N27: =SUMIF($Z$3:$FB$3,N$7,$Z27:$FB27) | O27: =SUMIF($Z$3:$FB$3,O$7,$Z27:$FB27) | P27: =SUMIF($Z$3:$FB$3,P$7,$Z27:$FB27) | Q27: =SUMIF($Z$3:$FB$3,Q$7,$Z27:$FB27) | R27: =SUMIF($Z$3:$FB$3,R$7,$Z27:$FB27) | S27: =SUMIF($Z$3:$FB$3,S$7,$Z27:$FB27) | T27: =SUMIF($Z$3:$FB$3,T$7,$Z27:$FB27) | U27: =SUMIF($Z$3:$FB$3,U$7,$Z27:$FB27) | ... X27: =SUMIF($Z$3:$FB$3,X$7,$Z27:$FB27) | Z27: 0 | AA27: =$J$27*AA53 | AB27: =$J$27*AB53 | AC27: =$J$27*AC53 | AD27: =$J$27*AD53 | AE27: =$J$27*AE53 | AF27: =$J$27*AF53 | AG27: =$J$27*AG53 | AH27: =$J$27*AH53 | ... FB27: =$J$27*FB53
I28: Parking Income | J28: =F79 | L28: =SUMIF($Z$4:$FB$4,"<="&$G$18,$Z28:$FB28) | N28: =SUMIF($Z$3:$FB$3,N$7,$Z28:$FB28) | O28: =SUMIF($Z$3:$FB$3,O$7,$Z28:$FB28) | P28: =SUMIF($Z$3:$FB$3,P$7,$Z28:$FB28) | Q28: =SUMIF($Z$3:$FB$3,Q$7,$Z28:$FB28) | R28: =SUMIF($Z$3:$FB$3,R$7,$Z28:$FB28) | S28: =SUMIF($Z$3:$FB$3,S$7,$Z28:$FB28) | T28: =SUMIF($Z$3:$FB$3,T$7,$Z28:$FB28) | U28: =SUMIF($Z$3:$FB$3,U$7,$Z28:$FB28) | ... X28: =SUMIF($Z$3:$FB$3,X$7,$Z28:$FB28) | Z28: 0 | AA28: =IFERROR($F$79*$E$79*AA12*(AA$4>=1),0) | AB28: =IFERROR($F$79*$E$79*AB12*(AB$4>=1),0) | AC28: =IFERROR($F$79*$E$79*AC12*(AC$4>=1),0) | AD28: =IFERROR($F$79*$E$79*AD12*(AD$4>=1),0) | AE28: =IFERROR($F$79*$E$79*AE12*(AE$4>=1),0) | AF28: =IFERROR($F$79*$E$79*AF12*(AF$4>=1),0) | AG28: =IFERROR($F$79*$E$79*AG12*(AG$4>=1),0) | AH28: =IFERROR($F$79*$E$79*AH12*(AH$4>=1),0) | ... FB28: =IFERROR($F$79*$E$79*FB12*(FB$4>=1),0)
B29: Sources & Uses at Closing | I29: Other Income | J29: =F80 | L29: =SUMIF($Z$4:$FB$4,"<="&$G$18,$Z29:$FB29) | N29: =SUMIF($Z$3:$FB$3,N$7,$Z29:$FB29) | O29: =SUMIF($Z$3:$FB$3,O$7,$Z29:$FB29) | P29: =SUMIF($Z$3:$FB$3,P$7,$Z29:$FB29) | Q29: =SUMIF($Z$3:$FB$3,Q$7,$Z29:$FB29) | R29: =SUMIF($Z$3:$FB$3,R$7,$Z29:$FB29) | S29: =SUMIF($Z$3:$FB$3,S$7,$Z29:$FB29) | T29: =SUMIF($Z$3:$FB$3,T$7,$Z29:$FB29) | U29: =SUMIF($Z$3:$FB$3,U$7,$Z29:$FB29) | ... X29: =SUMIF($Z$3:$FB$3,X$7,$Z29:$FB29) | Z29: 0 | AA29: =IFERROR($F$80*$E$80*AA12*(AA$4>=1),0) | AB29: =IFERROR($F$80*$E$80*AB12*(AB$4>=1),0) | AC29: =IFERROR($F$80*$E$80*AC12*(AC$4>=1),0) | AD29: =IFERROR($F$80*$E$80*AD12*(AD$4>=1),0) | AE29: =IFERROR($F$80*$E$80*AE12*(AE$4>=1),0) | AF29: =IFERROR($F$80*$E$80*AF12*(AF$4>=1),0) | AG29: =IFERROR($F$80*$E$80*AG12*(AG$4>=1),0) | AH29: =IFERROR($F$80*$E$80*AH12*(AH$4>=1),0) | ... FB29: =IFERROR($F$80*$E$80*FB12*(FB$4>=1),0)
B30: Sources | C30: % Total | D30: Closing | E30: % Total | F30: Refinance | G30: At Exit | I30: Total Other Income | L30: =SUMIF($Z$4:$FB$4,"<="&$G$18,$Z30:$FB30) | N30: =SUMIF($Z$3:$FB$3,N$7,$Z30:$FB30) | O30: =SUMIF($Z$3:$FB$3,O$7,$Z30:$FB30) | P30: =SUMIF($Z$3:$FB$3,P$7,$Z30:$FB30) | Q30: =SUMIF($Z$3:$FB$3,Q$7,$Z30:$FB30) | R30: =SUMIF($Z$3:$FB$3,R$7,$Z30:$FB30) | S30: =SUMIF($Z$3:$FB$3,S$7,$Z30:$FB30) | T30: =SUMIF($Z$3:$FB$3,T$7,$Z30:$FB30) | U30: =SUMIF($Z$3:$FB$3,U$7,$Z30:$FB30) | ... X30: =SUMIF($Z$3:$FB$3,X$7,$Z30:$FB30) | Z30: 0 | AA30: =SUM(AA27:AA29) | AB30: =SUM(AB27:AB29) | AC30: =SUM(AC27:AC29) | AD30: =SUM(AD27:AD29) | AE30: =SUM(AE27:AE29) | AF30: =SUM(AF27:AF29) | AG30: =SUM(AG27:AG29) | AH30: =SUM(AH27:AH29) | ... FB30: =SUM(FB27:FB29)
B31: GP Equity | C31: =D31/$D$34 | D31: =(D41-D46)*G7 | E31: =F31/$F$34 | F31: =(F34-F33)*G7 | G31: =(G34-G33)*G7
B32: Aequitas Equity | C32: =D32/$D$34 | D32: =(D41-D46)*F7 | E32: =F32/$F$34 | F32: =(F34-F33)*F7 | G32: =(G34-G33)*F7 | I32: Vacancy Loss | L32: =SUMIF($Z$4:$FB$4,"<="&$G$18,$Z32:$FB32) | N32: =SUMIF($Z$3:$FB$3,N$7,$Z32:$FB32) | O32: =SUMIF($Z$3:$FB$3,O$7,$Z32:$FB32) | P32: =SUMIF($Z$3:$FB$3,P$7,$Z32:$FB32) | Q32: =SUMIF($Z$3:$FB$3,Q$7,$Z32:$FB32) | R32: =SUMIF($Z$3:$FB$3,R$7,$Z32:$FB32) | S32: =SUMIF($Z$3:$FB$3,S$7,$Z32:$FB32) | T32: =SUMIF($Z$3:$FB$3,T$7,$Z32:$FB32) | U32: =SUMIF($Z$3:$FB$3,U$7,$Z32:$FB32) | ... X32: =SUMIF($Z$3:$FB$3,X$7,$Z32:$FB32) | Z32: 0 | AA32: =-IFERROR(INDEX($C85:$G85,MATCH(YEAR(AA$6),$C$83:$G$83,0)),$G$85)*(SUM(AA$24,AA$30)) | AB32: =-IFERROR(INDEX($C85:$G85,MATCH(YEAR(AB$6),$C$83:$G$83,0)),$G$85)*(SUM(AB$24,AB$30)) | AC32: =-IFERROR(INDEX($C85:$G85,MATCH(YEAR(AC$6),$C$83:$G$83,0)),$G$85)*(SUM(AC$24,AC$30)) | AD32: =-IFERROR(INDEX($C85:$G85,MATCH(YEAR(AD$6),$C$83:$G$83,0)),$G$85)*(SUM(AD$24,AD$30)) | AE32: =-IFERROR(INDEX($C85:$G85,MATCH(YEAR(AE$6),$C$83:$G$83,0)),$G$85)*(SUM(AE$24,AE$30)) | AF32: =-IFERROR(INDEX($C85:$G85,MATCH(YEAR(AF$6),$C$83:$G$83,0)),$G$85)*(SUM(AF$24,AF$30)) | AG32: =-IFERROR(INDEX($C85:$G85,MATCH(YEAR(AG$6),$C$83:$G$83,0)),$G$85)*(SUM(AG$24,AG$30)) | AH32: =-IFERROR(INDEX($C85:$G85,MATCH(YEAR(AH$6),$C$83:$G$83,0)),$G$85)*(SUM(AH$24,AH$30)) | ... FB32: =-IFERROR(INDEX($C85:$G85,MATCH(YEAR(FB$6),$C$83:$G$83,0)),$G$85)*(SUM(FB$24,FB$30))
B33: Debt | C33: =D33/$D$34 | D33: =D46 | E33: =F33/$F$34 | F33: =G46 | G33: =INDEX($Z$164:$FB$164,MATCH(G18,$Z$4:$FB$4,0)) | I33: Bad Debt | J33: =C86 | L33: =SUMIF($Z$4:$FB$4,"<="&$G$18,$Z33:$FB33) | N33: =SUMIF($Z$3:$FB$3,N$7,$Z33:$FB33) | O33: =SUMIF($Z$3:$FB$3,O$7,$Z33:$FB33) | P33: =SUMIF($Z$3:$FB$3,P$7,$Z33:$FB33) | Q33: =SUMIF($Z$3:$FB$3,Q$7,$Z33:$FB33) | R33: =SUMIF($Z$3:$FB$3,R$7,$Z33:$FB33) | S33: =SUMIF($Z$3:$FB$3,S$7,$Z33:$FB33) | T33: =SUMIF($Z$3:$FB$3,T$7,$Z33:$FB33) | U33: =SUMIF($Z$3:$FB$3,U$7,$Z33:$FB33) | ... X33: =SUMIF($Z$3:$FB$3,X$7,$Z33:$FB33) | Z33: 0 | AA33: =-IFERROR(INDEX($C86:$G86,MATCH(YEAR(AA$6),$C$83:$G$83,0)),$G$86)*(SUM(AA$24,AA$30)) | AB33: =-IFERROR(INDEX($C86:$G86,MATCH(YEAR(AB$6),$C$83:$G$83,0)),$G$86)*(SUM(AB$24,AB$30)) | AC33: =-IFERROR(INDEX($C86:$G86,MATCH(YEAR(AC$6),$C$83:$G$83,0)),$G$86)*(SUM(AC$24,AC$30)) | AD33: =-IFERROR(INDEX($C86:$G86,MATCH(YEAR(AD$6),$C$83:$G$83,0)),$G$86)*(SUM(AD$24,AD$30)) | AE33: =-IFERROR(INDEX($C86:$G86,MATCH(YEAR(AE$6),$C$83:$G$83,0)),$G$86)*(SUM(AE$24,AE$30)) | AF33: =-IFERROR(INDEX($C86:$G86,MATCH(YEAR(AF$6),$C$83:$G$83,0)),$G$86)*(SUM(AF$24,AF$30)) | AG33: =-IFERROR(INDEX($C86:$G86,MATCH(YEAR(AG$6),$C$83:$G$83,0)),$G$86)*(SUM(AG$24,AG$30)) | AH33: =-IFERROR(INDEX($C86:$G86,MATCH(YEAR(AH$6),$C$83:$G$83,0)),$G$86)*(SUM(AH$24,AH$30)) | ... FB33: =-IFERROR(INDEX($C86:$G86,MATCH(YEAR(FB$6),$C$83:$G$83,0)),$G$86)*(SUM(FB$24,FB$30))
B34: Total | C34: =D34/$D$34 | D34: =SUM(D31:D33) | E34: =F34/$F$34 | F34: =F24 | G34: =G24 | I34: Concessions | J34: =C87 | L34: =SUMIF($Z$4:$FB$4,"<="&$G$18,$Z34:$FB34) | N34: =SUMIF($Z$3:$FB$3,N$7,$Z34:$FB34) | O34: =SUMIF($Z$3:$FB$3,O$7,$Z34:$FB34) | P34: =SUMIF($Z$3:$FB$3,P$7,$Z34:$FB34) | Q34: =SUMIF($Z$3:$FB$3,Q$7,$Z34:$FB34) | R34: =SUMIF($Z$3:$FB$3,R$7,$Z34:$FB34) | S34: =SUMIF($Z$3:$FB$3,S$7,$Z34:$FB34) | T34: =SUMIF($Z$3:$FB$3,T$7,$Z34:$FB34) | U34: =SUMIF($Z$3:$FB$3,U$7,$Z34:$FB34) | ... X34: =SUMIF($Z$3:$FB$3,X$7,$Z34:$FB34) | Z34: 0 | AA34: =-IFERROR(INDEX($C87:$G87,MATCH(YEAR(AA$6),$C$83:$G$83,0)),$G$87)*(SUM(AA$24,AA$30)) | AB34: =-IFERROR(INDEX($C87:$G87,MATCH(YEAR(AB$6),$C$83:$G$83,0)),$G$87)*(SUM(AB$24,AB$30)) | AC34: =-IFERROR(INDEX($C87:$G87,MATCH(YEAR(AC$6),$C$83:$G$83,0)),$G$87)*(SUM(AC$24,AC$30)) | AD34: =-IFERROR(INDEX($C87:$G87,MATCH(YEAR(AD$6),$C$83:$G$83,0)),$G$87)*(SUM(AD$24,AD$30)) | AE34: =-IFERROR(INDEX($C87:$G87,MATCH(YEAR(AE$6),$C$83:$G$83,0)),$G$87)*(SUM(AE$24,AE$30)) | AF34: =-IFERROR(INDEX($C87:$G87,MATCH(YEAR(AF$6),$C$83:$G$83,0)),$G$87)*(SUM(AF$24,AF$30)) | AG34: =-IFERROR(INDEX($C87:$G87,MATCH(YEAR(AG$6),$C$83:$G$83,0)),$G$87)*(SUM(AG$24,AG$30)) | AH34: =-IFERROR(INDEX($C87:$G87,MATCH(YEAR(AH$6),$C$83:$G$83,0)),$G$87)*(SUM(AH$24,AH$30)) | ... FB34: =-IFERROR(INDEX($C87:$G87,MATCH(YEAR(FB$6),$C$83:$G$83,0)),$G$87)*(SUM(FB$24,FB$30))
I35: Model Unit Loss | L35: =SUMIF($Z$4:$FB$4,"<="&$G$18,$Z35:$FB35) | N35: =SUMIF($Z$3:$FB$3,N$7,$Z35:$FB35) | O35: =SUMIF($Z$3:$FB$3,O$7,$Z35:$FB35) | P35: =SUMIF($Z$3:$FB$3,P$7,$Z35:$FB35) | Q35: =SUMIF($Z$3:$FB$3,Q$7,$Z35:$FB35) | R35: =SUMIF($Z$3:$FB$3,R$7,$Z35:$FB35) | S35: =SUMIF($Z$3:$FB$3,S$7,$Z35:$FB35) | T35: =SUMIF($Z$3:$FB$3,T$7,$Z35:$FB35) | U35: =SUMIF($Z$3:$FB$3,U$7,$Z35:$FB35) | ... X35: =SUMIF($Z$3:$FB$3,X$7,$Z35:$FB35) | Z35: =(-IFERROR(INDEX($C88:$G88,MATCH(YEAR(Z$6),$C$83:$G$83,0)),$G$88)*Z19)*(Z4>=1) | AA35: =(-IFERROR(INDEX($C88:$G88,MATCH(YEAR(AA$6),$C$83:$G$83,0)),$G$88)*AA19)*(AA4>=1) | AB35: =(-IFERROR(INDEX($C88:$G88,MATCH(YEAR(AB$6),$C$83:$G$83,0)),$G$88)*AB19)*(AB4>=1) | AC35: =(-IFERROR(INDEX($C88:$G88,MATCH(YEAR(AC$6),$C$83:$G$83,0)),$G$88)*AC19)*(AC4>=1) | AD35: =(-IFERROR(INDEX($C88:$G88,MATCH(YEAR(AD$6),$C$83:$G$83,0)),$G$88)*AD19)*(AD4>=1) | AE35: =(-IFERROR(INDEX($C88:$G88,MATCH(YEAR(AE$6),$C$83:$G$83,0)),$G$88)*AE19)*(AE4>=1) | AF35: =(-IFERROR(INDEX($C88:$G88,MATCH(YEAR(AF$6),$C$83:$G$83,0)),$G$88)*AF19)*(AF4>=1) | AG35: =(-IFERROR(INDEX($C88:$G88,MATCH(YEAR(AG$6),$C$83:$G$83,0)),$G$88)*AG19)*(AG4>=1) | ... FB35: =(-IFERROR(INDEX($C88:$G88,MATCH(YEAR(FB$6),$C$83:$G$83,0)),$G$88)*FB19)*(FB4>=1)
B36: Uses | C36: $/Unit | D36: Total | E36: At Closing | F36: Start Month | G36: Duration | I36: Total Vacancy & Collection | L36: =SUMIF($Z$4:$FB$4,"<="&$G$18,$Z36:$FB36) | N36: =SUMIF($Z$3:$FB$3,N$7,$Z36:$FB36) | O36: =SUMIF($Z$3:$FB$3,O$7,$Z36:$FB36) | P36: =SUMIF($Z$3:$FB$3,P$7,$Z36:$FB36) | Q36: =SUMIF($Z$3:$FB$3,Q$7,$Z36:$FB36) | R36: =SUMIF($Z$3:$FB$3,R$7,$Z36:$FB36) | S36: =SUMIF($Z$3:$FB$3,S$7,$Z36:$FB36) | T36: =SUMIF($Z$3:$FB$3,T$7,$Z36:$FB36) | U36: =SUMIF($Z$3:$FB$3,U$7,$Z36:$FB36) | ... X36: =SUMIF($Z$3:$FB$3,X$7,$Z36:$FB36) | Z36: =SUM(Z32:Z35) | AA36: =SUM(AA32:AA35) | AB36: =SUM(AB32:AB35) | AC36: =SUM(AC32:AC35) | AD36: =SUM(AD32:AD35) | AE36: =SUM(AE32:AE35) | AF36: =SUM(AF32:AF35) | AG36: =SUM(AG32:AG35) | ... FB36: =SUM(FB32:FB35)
B37: Acquisition Price | C37: =D37/$C$75 | D37: =D24 | E37: =Inputs!C12 | F37: =Inputs!C16 | G37: =Inputs!C20
B38: =Inputs!C11 | C38: =D38/$C$75 | D38: =B38*D37 | E38: =Inputs!C13 | F38: =Inputs!C17 | G38: =Inputs!C21 | I38: Effective Gross Income | L38: =SUMIF($Z$4:$FB$4,"<="&$G$18,$Z38:$FB38) | N38: =SUMIF($Z$3:$FB$3,N$7,$Z38:$FB38) | O38: =SUMIF($Z$3:$FB$3,O$7,$Z38:$FB38) | P38: =SUMIF($Z$3:$FB$3,P$7,$Z38:$FB38) | Q38: =SUMIF($Z$3:$FB$3,Q$7,$Z38:$FB38) | R38: =SUMIF($Z$3:$FB$3,R$7,$Z38:$FB38) | S38: =SUMIF($Z$3:$FB$3,S$7,$Z38:$FB38) | T38: =SUMIF($Z$3:$FB$3,T$7,$Z38:$FB38) | U38: =SUMIF($Z$3:$FB$3,U$7,$Z38:$FB38) | ... X38: =SUMIF($Z$3:$FB$3,X$7,$Z38:$FB38) | Z38: =SUM(Z24,Z30,Z36) | AA38: =SUM(AA24,AA30,AA36) | AB38: =SUM(AB24,AB30,AB36) | AC38: =SUM(AC24,AC30,AC36) | AD38: =SUM(AD24,AD30,AD36) | AE38: =SUM(AE24,AE30,AE36) | AF38: =SUM(AF24,AF30,AF36) | AG38: =SUM(AG24,AG30,AG36) | ... FB38: =SUM(FB24,FB30,FB36)
B39: Working Capital/Reserve | C39: =D39/$C$75 | D39: =Inputs!C85 | E39: =Inputs!C14 | F39: =Inputs!C18 | G39: =Inputs!C22
B40: Financing Costs | C40: =D40/$C$75 | D40: =D49 | E40: =Inputs!C15 | F40: =Inputs!C19 | G40: =Inputs!C23 | I40: Operating Expenses
B41: Total | C41: =D41/$C$75 | D41: =SUM(D37:D40) | I41: Controllable Expenses | J41: $/Unit/Yr | L41: Total
I42: Payroll | J42: =Inputs!C72 | L42: =SUMIF($Z$4:$FB$4,"<="&$G$18,$Z42:$FB42) | N42: =SUMIF($Z$3:$FB$3,N$7,$Z42:$FB42) | O42: =SUMIF($Z$3:$FB$3,O$7,$Z42:$FB42) | P42: =SUMIF($Z$3:$FB$3,P$7,$Z42:$FB42) | Q42: =SUMIF($Z$3:$FB$3,Q$7,$Z42:$FB42) | R42: =SUMIF($Z$3:$FB$3,R$7,$Z42:$FB42) | S42: =SUMIF($Z$3:$FB$3,S$7,$Z42:$FB42) | T42: =SUMIF($Z$3:$FB$3,T$7,$Z42:$FB42) | U42: =SUMIF($Z$3:$FB$3,U$7,$Z42:$FB42) | ... X42: =SUMIF($Z$3:$FB$3,X$7,$Z42:$FB42) | Z42: 0 | AA42: =$J42/12*AA$14*$C$75 | AB42: =$J42/12*AB$14*$C$75 | AC42: =$J42/12*AC$14*$C$75 | AD42: =$J42/12*AD$14*$C$75 | AE42: =$J42/12*AE$14*$C$75 | AF42: =$J42/12*AF$14*$C$75 | AG42: =$J42/12*AG$14*$C$75 | AH42: =$J42/12*AH$14*$C$75 | ... FB42: =$J42/12*FB$14*$C$75
...

Sheet Inputs
B3: Item | C3: Value
B4: Acquisition Date BOP Mo | C4: 0
B5: Acquisition Date BOP Date | C5: 46174
B6: Acquisition Date Duration | C6: 0
B7: Senior/Bridge Loan Term (Months) | C7: 24
B8: NOI T-12 | C8: 557219.86
B9: Cap Rate Aequitas Valuation | C9: 0.083167144
B10: Total Sales Cost | C10: 0.02
B11: Closing Costs | C11: 0.0075
B12: Acquisition Price at Closing | C12: 1
B13: Closing Costs at Closing | C13: 1
B14: Working Capital/Reserve at Closing | C14: 1
B15: Financing Costs at Closing | C15: 1
... B80: Senior IO Periods/Amortization | C80: 24
B81: Property Name | C81: Milestone and Trails Portfolio
B82: Property Address | C82: 5070 Warm Springs Rd & 4531 Milgen Rd, Columbus, GA
B83: Hold Period (Years) | C83: 10
B84: Purchase Price | C84: 6700000
B85: Working Capital/Reserve Amount | C85: 495432.59
B86: LP Equity Share | C86: 0.85
B87: RUBS % | C87: 0.7
B88: Parking $/Unit/Mo | C88: 0
B89: Other Income $/Unit/Mo | C89: 75
B90: Pari Passu (1=Yes, 0=No) | C90: 0
B91: Millage Rate | C91: 0.018926798
B92: Special Assessment | C92: 0
B94: Unit Mix
B95: Unit Type | C95: Count | D95: Rent/Unit | E95: Avg Size
B96: 2bd/2ba - 5070 | C96: 32 | D96: 1230.39 | E96: 1100
B97: 2bd/2ba - 4531 | C97: 24 | D97: 1241.67 | E97: 1250
C98: 0 | D98: 0 | E98: 0
C99: 0 | D99: 0 | E99: 0
C100: 0 | D100: 0 | E100: 0
C101: 0 | D101: 0 | E101: 0
C102: 0 | D102: 0 | E102: 0
C103: 0 | D103: 0 | E103: 0
C104: 0 | D104: 0 | E104: 0
C105: 0 | D105: 0 | E105: 0
C106: 0 | D106: 0 | E106: 0
C107: 0 | D107: 0 | E107: 0
...
