Workbook
Name ______new1: #REF!
Name _____new1: #REF!
Name ___new1: #REF!
Name __new1: #REF!
Name _2004: #REF!
Name _2005: #REF!
Name _2006: #REF!
Name _2007: #REF!
Name _2008: #REF!
Name _2009: #REF!
Name _2010: #REF!
Name _2011: #REF!
Name _2012: #REF!
Name _2013: #REF!
Name _2013_: #REF!
Name _2014: #REF!
Name _2015: #REF!
Name _2016: #REF!
Name _2017: #REF!
Name _2018: #REF!
Name _2020: #REF!
Name _3000: #REF!
Name _3010: #REF!
Name _3019: #REF!
Name _3310: #REF!
Name _4320: #REF!
Name _4355: #REF!
Name _4405: #REF!
Name _4410: #REF!
Name _4445: #REF!
Name _4450: #REF!
Name _4452: #REF!
Name _4453: #REF!
Name _4480: #REF!
Name _4485: #REF!
Name _4496: #REF!
Name _4505: #REF!
Name _4555: #REF!
Name _4560: #REF!
Name _4710: #REF!
Name _4715: #REF!
Name _4830: #REF!
Name _4848: #REF!
Name _ADM2000: #REF!
Name _ADM2001: #REF!
Name _Bud02: #REF!
Name _Bud03: #REF!
Name _CAM96: #REF!
Name _CAM97: #REF!
Name _CAM98: #REF!
Name _DPU95: #REF!
Name _end1: IF([0]!Loan_Amount*[0]!Interest_Rate*[0]!Loan_Years*[0]!Loan_Start>0,1,0)
Name _EPU01: #REF!
Name _EPU02: #REF!
Name _EPU03: #REF!
Name _EPU04: #REF!
Name _EPU96: #REF!
Name _EPU97: #REF!
Name _EPU98: #REF!
Name _EPU99: #REF!

Sheet Underwriting
E1: Mo | F1: =F53 -> 0 | G1: =G53 -> 1 | H1: =H53 -> 2 | I1: =I53 -> 3 | J1: =J53 -> 4 | K1: =K53 -> 5 | L1: =L53 -> 6 | M1: =M53 -> 7 | ... FD1: =FD53 -> 154
E2: Date | F2: =F55 -> 46203 | G2: =G55 -> 46234 | H2: =H55 -> 46265 | I2: =I55 -> 46295 | J2: =J55 -> 46326 | K2: =K55 -> 46356 | L2: =L55 -> 46387 | M2: =M55 -> 46418 | ... FD2: =FD55 -> 50890
C3: Base Assumptions
C4: # | D4: 101 | AN4: Under Construction
C5: Property Name: | D5: 1424 Wake Forest Dr
C6: Address: | D6: 1424 Wake Forest Dr, Davis, CA | AN6: In Lease Up
C7: Timeline | K7: Income Analysis | S7: ACF Analysis | AH7: Sensitivities - Aequitas IRR/EM
E8: BOP Mo | F8: BOP Date | G8: Duration | H8: EOP Date | I8: EOP Mo | K8: MR Unit Breakdown | N8: Unit Count | O8: Rent/Unit | P8: Average Size | Q8: Rent PSF | U8: Pro Forma | AA8: Historical Financials | AH8: Senior Loan Interest Rate | AI8: =AJ8+0.25% -> 0.0775 | AJ8: =AK8+0.25% -> 0.075 | AK8: =AL8+0.25% -> 0.0725 | AL8: 0.07 | AM8: =AL8-0.25% -> 0.0675 | AN8: =AM8-0.25% -> 0.065 | AO8: =AN8-0.25% -> 0.0625
C9: Acquisition Date | E9: 0 | F9: 46203 | G9: 1 | H9: =EOMONTH(F9,E9) -> 46203 | I9: =INDEX($F$53:$FV$53,MATCH(H9,$F$55:$FV$55,0)) -> 0 | K9: Studio | N9: 0 | O9: 0 | P9: 0 | Q9: =IFERROR(+O9/P9,0) -> 0 | U9: Untrended | V9: $/Unit | W9: Refinance | X9: $/Unit | Y9: At Exit | Z9: $/Unit | AA9: T-3 | AB9: $/Unit | AC9: T-6 | AD9: $/Unit | AE9: T-12 | AF9: $/Unit | AH9: =CONCATENATE(TEXT($G$48,"0.00%")," / ",TEXT($G$49,"0.00x")) -> 16.80% / 2.40x | AI9: 15.30% / 2.36x | AJ9: 15.77% / 2.37x | AK9: 16.27% / 2.39x | AL9: 16.80% / 2.40x | AM9: 17.37% / 2.42x | AN9: 17.98% / 2.44x | AO9: 18.63% / 2.45x
C10: Hold Period | E10: =INDEX($F$53:$FV$53,MATCH(F10,$F$55:$FV$55,0)) -> 1 | F10: =EOMONTH(H9,1) -> 46234 | G10: 36 | H10: =EOMONTH(F10,G10-1) -> 47299 | I10: =INDEX($F$53:$FV$53,MATCH(H10,$F$55:$FV$55,0)) -> 36 | K10: 1 Bedroom | N10: 63 | O10: 1900 | P10: 766 | Q10: =IFERROR(+O10/P10,0) -> 2.4804178 | S10: Potential Market Rent | U10: =V10*$N$13*12 -> 1436400 | V10: =O13 -> 1900 | W10: =SUM(OFFSET(F71,0,$G$16,1,-12)) -> 1550119.4 | X10: =W10/$N$13 -> 24605.07 | Y10: =SUM(OFFSET(F71,0,$I$16,1,-12)) -> 1800644.7 | Z10: =Y10/$N$13 -> 28581.662 | AA10: 0 | AB10: =AA10/$N$13 -> 0 | AC10: 0 | AD10: =AC10/$N$13 -> 0 | AE10: 0 | AF10: =AE10/$N$13 -> 0 | AH10: General Inflation | AI10: =AJ10+0.25% -> 0.0375 | AJ10: =AK10+0.25% -> 0.035 | AK10: =AL10+0.25% -> 0.0325 | AL10: 0.03 | AM10: =AL10-0.5% -> 0.025 | AN10: =AM10-0.5% -> 0.02 | AO10: =AN10-0.5% -> 0.015
C11: Refinance | E11: =INDEX($F$53:$FV$53,MATCH(F11,$F$55:$FV$55,0)) -> 36 | F11: =EOMONTH(H10,0) -> 47299 | G11: 1 | H11: =EOMONTH(F11,G11-1) -> 47299 | I11: =INDEX($F$53:$FV$53,MATCH(H11,$F$55:$FV$55,0)) -> 36 | K11: 2 Bedroom | N11: 0 | O11: 0 | P11: 0 | Q11: =IFERROR(+O11/P11,0) -> 0 | S11: Loss to Lease | U11: 0 | V11: =U11/$N$13 -> 0 | W11: =SUM(OFFSET(F72,0,$G$16,1,-12)) -> -19376.493 | X11: =W11/$N$13 -> -307.56338 | Y11: =SUM(OFFSET(F72,0,$I$16,1,-12)) -> -22508.059 | Z11: =Y11/$N$13 -> -357.27078 | AA11: 0 | AB11: =AA11/$N$13 -> 0 | AC11: 0 | AD11: =AC11/$N$13 -> 0 | AE11: 0 | AF11: =AE11/$N$13 -> 0 | AH11: =CONCATENATE(TEXT($G$48,"0.00%")," / ",TEXT($G$49,"0.00x")) -> 16.80% / 2.40x | AI11: 18.49% / 2.61x | AJ11: 17.93% / 2.54x | AK11: 17.37% / 2.47x | AL11: 16.80% / 2.40x | AM11: 15.66% / 2.27x | AN11: 14.50% / 2.14x | AO11: 13.32% / 2.02x
C12: Hold Period | D12: 8 | E12: =INDEX($F$53:$FV$53,MATCH(F12,$F$55:$FV$55,0)) -> 37 | F12: =EOMONTH(H11,1) -> 47330 | G12: =I12-E12+1 -> 60 | H12: =EOMONTH(F9,D12*12) -> 49125 | I12: =INDEX($F$53:$FV$53,MATCH(H12,$F$55:$FV$55,0)) -> 96 | K12: 3 Bedroom | N12: 0 | O12: 0 | P12: 0 | Q12: =IFERROR(+O12/P12,0) -> 0 | S12: Gross Potential Rent | U12: =SUM(U10:U11) -> 1436400 | V12: =SUM(V10:V11) -> 1900 | W12: =SUM(W10:W11) -> 1530742.9 | X12: =W12/$N$13 -> 24297.507 | Y12: =SUM(Y10:Y11) -> 1778136.7 | Z12: =Y12/$N$13 -> 28224.392 | AA12: =SUM(AA10:AA11) -> 0 | AB12: =AA12/$N$13 -> 0 | AC12: =SUM(AC10:AC11) -> 0 | AD12: =AC12/$N$13 -> 0 | AE12: =SUM(AE10:AE11) -> 0 | AF12: =AE12/$N$13 -> 0 | AH12: Cap Reserve ($/Unit) | AI12: 500 | AJ12: =AI12+250 -> 750 | AK12: =AJ12+250 -> 1000 | AL12: =AK12+250 -> 1250 | AM12: =AL12+250 -> 1500 | AN12: =AM12+250 -> 1750 | AO12: =AN12+250 -> 2000
K13: Total/Avg (MR+BMR) | N13: =SUM(N9:N12) -> 63 | O13: =SUMPRODUCT(O9:O12,$N$9:$N$12)/$N$13 -> 1900 | P13: =SUMPRODUCT(P9:P12,$N$9:$N$12)/$N$13 -> 766 | Q13: =SUMPRODUCT(Q9:Q12,$N$9:$N$12)/$N$13 -> 2.4804178 | AH13: =CONCATENATE(TEXT($G$48,"0.00%")," / ",TEXT($G$49,"0.00x")) -> 16.80% / 2.40x | AI13: 16.80% / 2.40x | AJ13: 15.90% / 2.33x | AK13: 15.00% / 2.25x | AL13: 14.10% / 2.17x | AM13: 13.20% / 2.09x | AN13: 12.29% / 2.02x | AO13: 11.38% / 1.94x
C14: Valuation Analysis | S14: =K16 -> RUBS | U14: =U38*$N$16 -> 0 | V14: =U14/$N$13 -> 0 | W14: =SUM(OFFSET(F76,0,$G$16,1,-12)) -> 0 | X14: =W14/$N$13 -> 0 | Y14: =SUM(OFFSET(F76,0,$I$16,1,-12)) -> 0 | Z14: =Y14/$N$13 -> 0 | AA14: 0 | AB14: =AA14/$N$13 -> 0 | AC14: 0 | AD14: =AC14/$N$13 -> 0 | AE14: 0 | AF14: =AE14/$N$13 -> 0
C15: Entry/Equity Valuation | E15: Residual Analysi: | F15: Refinance | G15: $/Unit | H15: Exit | I15: $/Unit | K15: Other Income | N15: % | O15: Count | P15: $ / Unit / Mo | Q15: Annual Total | S15: =K17 -> Parking | U15: =O17*P17*12 -> 0 | V15: =U15/$N$13 -> 0 | W15: =SUM(OFFSET(F77,0,$G$16,1,-12)) -> 0 | X15: =W15/$N$13 -> 0 | Y15: =SUM(OFFSET(F77,0,$I$16,1,-12)) -> 0 | Z15: =Y15/$N$13 -> 0 | AA15: 0 | AB15: =AA15/$N$13 -> 0 | AC15: 0 | AD15: =AC15/$N$13 -> 0 | AE15: 0 | AF15: =AE15/$N$13 -> 0 | AH15: Inputs | AI15: Values
C16: TTM EBITDA/NOI | D16: 796926.06 | E16: Date | Month | F16: =F11 -> 47299 | G16: =E11 -> 36 | H16: =H12 -> 49125 | I16: =I12 -> 96 | K16: RUBS | N16: 0 | O16: =$N$13 -> 63 | P16: =IFERROR(Q16/O16,0) -> 0 | Q16: =N16*U38 -> 0 | S16: =K18 -> Other | U16: =Q18 -> 0 | V16: =U16/$N$13 -> 0 | W16: =SUM(OFFSET(F78,0,$G$16,1,-12)) -> 0 | X16: =W16/$N$13 -> 0 | Y16: =SUM(OFFSET(F78,0,$I$16,1,-12)) -> 0 | Z16: =Y16/$N$13 -> 0 | AA16: 0 | AB16: =AA16/$N$13 -> 0 | AC16: 0 | AD16: =AC16/$N$13 -> 0 | AE16: 0 | AF16: =AE16/$N$13 -> 0 | AH16: Senior Loan Interest Rate | AI16: 0.07
C17: Capex Reserve | D17: 0 | E17: NOI (TTM) | F17: =INDEX($F$122:$FV$122,MATCH(G16,$F$53:$FV$53,0)) -> 842257.03 | H17: =INDEX($F$122:$FV$122,MATCH(I16,$F$53:$FV$53,0)) -> 978379.9 | K17: Parking | O17: =$N$13 -> 63 | P17: 0 | Q17: =P17*O17*12 -> 0 | S17: Total Other Income | U17: =SUM(U14:U16) -> 0 | V17: =SUM(V14:V16) -> 0 | W17: =SUM(W14:W16) -> 0 | X17: =W17/$N$13 -> 0 | Y17: =SUM(Y14:Y16) -> 0 | Z17: =Y17/$N$13 -> 0 | AA17: =SUM(AA14:AA16) -> 0 | AB17: =AA17/$N$13 -> 0 | AC17: =SUM(AC14:AC16) -> 0 | AD17: =AC17/$N$13 -> 0 | AE17: =SUM(AE14:AE16) -> 0 | AF17: =AE17/$N$13 -> 0 | AH17: General Inflation | AI17: 0.03
C18: Adjusted EBITDA/NOI | D18: =D16-D17 -> 796926.06 | E18: Cap Rate | F18: 0.06 | H18: =F18 -> 0.06 | K18: Other | N18: =Q18/U10 -> 0 | O18: =$N$13 -> 63 | P18: 0 | Q18: =O18*P18*12 -> 0 | AH18: Cap Reserve ($/Unit) | AI18: 500
C19: Cap Rate | D19: 0.069949623 | E19: Gross Value | F19: =F17/F18 -> 14037617 | G19: =F19/$N$13 -> 222819.32 | H19: =H17/H18 -> 16306332 | I19: =H19/$N$13 -> 258830.66 | K19: Total Other Income | Q19: =SUM(Q16:Q18) -> 0 | S19: =K23 -> Vacancy Loss | U19: =-SUM($U$12,$U$17)*$M23 -> -71820 | V19: =U19/$N$13 -> -1140 | W19: =SUM(OFFSET(F81,0,$G$16,1,-12)) -> -76537.147 | X19: =W19/$N$13 -> -1214.8753 | Y19: =SUM(OFFSET(F81,0,$I$16,1,-12)) -> -88906.834 | Z19: =Y19/$N$13 -> -1411.2196 | AA19: 0 | AB19: =AA19/$N$13 -> 0 | AC19: 0 | AD19: =AC19/$N$13 -> 0 | AE19: 0 | AF19: =AE19/$N$13 -> 0
C20: Gross Value | D20: =D18/D19 -> 11392857 | E20: Value Adjustments | F20: 0 | H20: 0 | S20: =K24 -> Bad Debt | U20: =-SUM($U$12,$U$17)*$M24 -> -3591 | V20: =U20/$N$13 -> -57 | W20: =SUM(OFFSET(F82,0,$G$16,1,-12)) -> -3826.8573 | X20: =W20/$N$13 -> -60.743767 | Y20: =SUM(OFFSET(F82,0,$I$16,1,-12)) -> -4445.3417 | Z20: =Y20/$N$13 -> -70.560979 | AA20: 0 | AB20: =AA20/$N$13 -> 0 | AC20: 0 | AD20: =AC20/$N$13 -> 0 | AE20: 0 | AF20: =AE20/$N$13 -> 0
C21: $/Unit | D21: =D20/N13 -> 180839 | E21: Net Gross Value | F21: =F19+F20 -> 14037617 | G21: =F21/$N$13 -> 222819.32 | H21: =H19+H20 -> 16306332 | I21: =H21/$N$13 -> 258830.66 | K21: Income Adjustments | M21: =IF(MONTH(F9)=12,YEAR(F9)+1,YEAR(F9)) -> 2026 | N21: =M21+1 -> 2027 | O21: =N21+1 -> 2028 | P21: =O21+1 -> 2029 | Q21: =P21+1 -> 2030 | S21: =K25 -> Concessions | U21: =-SUM($U$12,$U$17)*$M25 -> -3591 | V21: =U21/$N$13 -> -57 | W21: =SUM(OFFSET(F83,0,$G$16,1,-12)) -> -3826.8573 | X21: =W21/$N$13 -> -60.743767 | Y21: =SUM(OFFSET(F83,0,$I$16,1,-12)) -> -4445.3417 | Z21: =Y21/$N$13 -> -70.560979 | AA21: 0 | AB21: =AA21/$N$13 -> 0 | AC21: 0 | AD21: =AC21/$N$13 -> 0 | AE21: 0 | AF21: =AE21/$N$13 -> 0
K22: Loss to Lease | M22: 0.0125 | N22: 0.0125 | O22: 0.0125 | P22: 0.0125 | Q22: 0.0125 | S22: =K26 -> Model Units | U22: =-O13*M26*12 -> 0 | V22: =U22/$N$13 -> 0 | W22: =SUM(OFFSET(F84,0,$G$16,1,-12)) -> 0 | X22: =W22/$N$13 -> 0 | Y22: =SUM(OFFSET(F84,0,$I$16,1,-12)) -> 0 | Z22: =Y22/$N$13 -> 0 | AA22: 0 | AB22: =AA22/$N$13 -> 0 | AC22: 0 | AD22: =AC22/$N$13 -> 0 | AE22: 0 | AF22: =AE22/$N$13 -> 0
C23: Less: Deferred Capex | D23: 0 | E23: Sales Costs | F23: Total | G23: $/Unit | H23: Total | I23: $/Unit | K23: Vacancy Loss | M23: 0.05 | N23: 0.05 | O23: 0.05 | P23: 0.05 | Q23: 0.05 | S23: Total Income Adjustments | U23: =SUM(U19:U22) -> -79002 | V23: =SUM(V19:V22) -> -1254 | W23: =SUM(W19:W22) -> -84190.861 | X23: =W23/$N$13 -> -1336.3629 | Y23: =SUM(Y19:Y22) -> -97797.517 | Z23: =Y23/$N$13 -> -1552.3415 | AA23: =SUM(AA19:AA22) -> 0 | AB23: =AA23/$N$13 -> 0 | AC23: =SUM(AC19:AC22) -> 0 | AD23: =AC23/$N$13 -> 0 | AE23: =SUM(AE19:AE22) -> 0 | AF23: =AE23/$N$13 -> 0
C24: Less: Outstanding Debt | D24: 6266071.4 | E24: 0.0025 | F24: =F$21*$E24 -> 35094.043 | G24: =F24/$N$13 -> 557.0483 | H24: =H$21*$E24 -> 40765.829 | I24: =H24/$N$13 -> 647.07666 | K24: Bad Debt | M24: 0.0025 | N24: 0.0025 | O24: 0.0025 | P24: 0.0025 | Q24: 0.0025
C25: Equity Value | D25: =D20-SUM(D23:D24) -> 5126785.7 | E25: 0.0025 | F25: =F$21*$E25 -> 35094.043 | G25: =F25/$N$13 -> 557.0483 | H25: =H$21*$E25 -> 40765.829 | I25: =H25/$N$13 -> 647.07666 | K25: Concessions | M25: 0.0025 | N25: 0.0025 | O25: 0.0025 | P25: 0.0025 | Q25: 0.0025 | S25: EGI | U25: =SUM(U12,U17,U23) -> 1357398 | V25: =SUM(V12,V17,V23) -> 646 | W25: =SUM(W12,W17,W23) -> 1446552.1 | X25: =SUM(X12,X17,X23) -> 22961.144 | Y25: =SUM(Y12,Y17,Y23) -> 1680339.2 | Z25: =SUM(Z12,Z17,Z23) -> 26672.05 | AA25: =SUM(AA12,AA17,AA23) -> 0 | AB25: =SUM(AB12,AB17,AB23) -> 0 | ... AF25: =SUM(AF12,AF17,AF23) -> 0
C26: Aequitas Equity Contributions | D26: =D25*D46 -> 769017.86 | E26: 0.0025 | F26: =F$21*$E26 -> 35094.043 | G26: =F26/$N$13 -> 557.0483 | H26: =H$21*$E26 -> 40765.829 | I26: =H26/$N$13 -> 647.07666 | K26: Model Units | M26: 0 | N26: 0 | O26: 0 | P26: 0 | Q26: 0
C27: Closing Costs % | D27: 0.01 | E27: 0.0025 | F27: =F$21*$E27 -> 35094.043 | G27: =F27/$N$13 -> 557.0483 | H27: =H$21*$E27 -> 40765.829 | I27: =H27/$N$13 -> 647.07666 | K27: Growth Assumptions | M27: =IF(MONTH(F9)=12,YEAR(F9)+1,YEAR(F9)) -> 2026 | N27: =M27+1 -> 2027 | O27: =N27+1 -> 2028 | P27: =O27+1 -> 2029 | Q27: =P27+1 -> 2030 | S27: Opex
C28: Closing Costs $ | D28: =D27*D20 -> 113928.57 | E28: =SUM(E24:E27) -> 0.01 | F28: =SUM(F24:F27) -> 140376.17 | G28: =F28/$N$13 -> 2228.1932 | H28: =SUM(H24:H27) -> 163063.32 | I28: =H28/$N$13 -> 2588.3066 | K28: Market Rent | M28: =AI17 -> 0.03 | N28: =M28 -> 0.03 | O28: =N28 -> 0.03 | P28: =O28 -> 0.03 | Q28: =P28 -> 0.03 | S28: Payroll | U28: =V28*$N$13 -> 431550 | V28: 6850 | W28: =SUM(OFFSET(F91,0,$G$16,1,-12)) -> 465715.7 | X28: =W28/$N$13 -> 7392.3128 | Y28: =SUM(OFFSET(F91,0,$I$16,1,-12)) -> 540983.18 | Z28: =Y28/$N$13 -> 8587.0346 | AA28: 0 | AB28: =AA28/$N$13 -> 0 | AC28: 0 | AD28: =AC28/$N$13 -> 0 | AE28: 0 | AF28: =AE28/$N$13 -> 0
E29: Net Sales Proceeds | F29: =F21-F28 -> 13897241 | G29: =G21-G28 -> 220591.13 | H29: =H21-H28 -> 16143268 | I29: =I21-I28 -> 256242.36 | K29: Other Income | M29: =M28 -> 0.03 | N29: =M29 -> 0.03 | O29: =N29 -> 0.03 | P29: =O29 -> 0.03 | Q29: =P29 -> 0.03 | S29: Admin | U29: =V29*$N$13 -> 0 | V29: 0 | W29: =SUM(OFFSET(F92,0,$G$16,1,-12)) -> 0 | X29: =W29/$N$13 -> 0 | Y29: =SUM(OFFSET(F92,0,$I$16,1,-12)) -> 0 | Z29: =Y29/$N$13 -> 0 | AA29: 0 | AB29: =AA29/$N$13 -> 0 | AC29: 0 | AD29: =AC29/$N$13 -> 0 | AE29: 0 | AF29: =AE29/$N$13 -> 0
K30: Operating Expenses | M30: =M29 -> 0.03 | N30: =M30 -> 0.03 | O30: =N30 -> 0.03 | P30: =O30 -> 0.03 | Q30: =P30 -> 0.03 | S30: Marketing | U30: =V30*$N$13 -> 0 | V30: 0 | W30: =SUM(OFFSET(F93,0,$G$16,1,-12)) -> 0 | X30: =W30/$N$13 -> 0 | Y30: =SUM(OFFSET(F93,0,$I$16,1,-12)) -> 0 | Z30: =Y30/$N$13 -> 0 | AA30: 0 | AB30: =AA30/$N$13 -> 0 | AC30: 0 | AD30: =AC30/$N$13 -> 0 | AE30: 0 | AF30: =AE30/$N$13 -> 0
C31: Financing Assumptions | K31: Property Taxes | M31: =M30 -> 0.03 | N31: =M31 -> 0.03 | O31: =N31 -> 0.03 | P31: =O31 -> 0.03 | Q31: =P31 -> 0.03 | S31: R&M | U31: =V31*$N$13 -> 0 | V31: 0 | W31: =SUM(OFFSET(F94,0,$G$16,1,-12)) -> 0 | X31: =W31/$N$13 -> 0 | Y31: =SUM(OFFSET(F94,0,$I$16,1,-12)) -> 0 | Z31: =Y31/$N$13 -> 0 | AA31: 0 | AB31: =AA31/$N$13 -> 0 | AC31: 0 | AD31: =AC31/$N$13 -> 0 | AE31: 0 | AF31: =AE31/$N$13 -> 0
C32: Senior Financing | E32: Senior Financing | H32: Refinance | S32: Contract Service | U32: =V32*$N$13 -> 0 | V32: 0 | W32: =SUM(OFFSET(F95,0,$G$16,1,-12)) -> 0 | X32: =W32/$N$13 -> 0 | Y32: =SUM(OFFSET(F95,0,$I$16,1,-12)) -> 0 | Z32: =Y32/$N$13 -> 0 | AA32: 0 | AB32: =AA32/$N$13 -> 0 | AC32: 0 | AD32: =AC32/$N$13 -> 0 | AE32: 0 | AF32: =AE32/$N$13 -> 0
C33: Lender | F33: TBD | G33: Lender | I33: TBD | K33: Property Taxes | S33: Turnover | U33: =V33*$N$13 -> 0 | V33: 0 | W33: =SUM(OFFSET(F96,0,$G$16,1,-12)) -> 0 | X33: =W33/$N$13 -> 0 | Y33: =SUM(OFFSET(F96,0,$I$16,1,-12)) -> 0 | Z33: =Y33/$N$13 -> 0 | AA33: 0 | AB33: =AA33/$N$13 -> 0 | AC33: 0 | AD33: =AC33/$N$13 -> 0 | AE33: 0 | AF33: =AE33/$N$13 -> 0
C34: Loan Proceeds | E34: 0.55 | F34: 6266071.4 | G34: Loan Proceeds | H34: DSCR | I34: =INDEX($I$40:$I$42,MATCH(H34,$G$40:$G$42,0)) -> 8883611.7 | M34: Current | N34: Next Buyer | O34: Note | S34: Other | U34: =V34*$N$13 -> 0 | V34: 0 | W34: =SUM(OFFSET(F97,0,$G$16,1,-12)) -> 0 | X34: =W34/$N$13 -> 0 | Y34: =SUM(OFFSET(F97,0,$I$16,1,-12)) -> 0 | Z34: =Y34/$N$13 -> 0 | AA34: 0 | AB34: =AA34/$N$13 -> 0 | AC34: 0 | AD34: =AC34/$N$13 -> 0 | AE34: 0 | AF34: =AE34/$N$13 -> 0
C35: Term | E35: 36 | F35: =EOMONTH(F9,E35) -> 47299 | G35: Term | H35: 360 | I35: =EOMONTH(F35,H35-1) -> 58226 | K35: Assessed Value | M35: 0 | N35: 0 | S35: Total Controllable Expenses | U35: =SUM(U28:U34) -> 431550 | V35: =SUM(V28:V34) -> 6850 | W35: =SUM(W28:W34) -> 465715.7 | X35: =SUM(X28:X34) -> 7392.3128 | Y35: =SUM(Y28:Y34) -> 540983.18 | Z35: =SUM(Z28:Z34) -> 8587.0346 | AA35: =SUM(AA28:AA34) -> 0 | AB35: =AA35/$N$13 -> 0 | AC35: =SUM(AC28:AC34) -> 0 | AD35: =AC35/$N$13 -> 0 | AE35: =SUM(AE28:AE34) -> 0 | AF35: =AE35/$N$13 -> 0
C36: Interest Rate | E36: Fixed | F36: =AI16 -> 0.07 | G36: Interest Rate | H36: Fixed | I36: =F36-0.5% -> 0.065 | K36: Assessed Value/Unit | M36: 0 | N36: 0
C37: Financing Costs | E37: 0.01 | F37: =E37*F34 -> 62660.714 | G37: Financing Costs | H37: 0.005 | I37: =H37*I34 -> 44418.058 | K37: Assessment % | M37: 1 | N37: =M37 -> 1 | S37: Insurance | U37: =V37*$N$13 -> 12600 | V37: 200 | W37: =SUM(OFFSET(F101,0,$G$16,1,-12)) -> 13597.539 | X37: =W37/$N$13 -> 215.83395 | Y37: =SUM(OFFSET(F101,0,$I$16,1,-12)) -> 15795.129 | Z37: =Y37/$N$13 -> 250.71634 | AA37: 0 | AB37: =AA37/$N$13 -> 0 | AC37: 0 | AD37: =AC37/$N$13 -> 0 | AE37: 0 | AF37: =AE37/$N$13 -> 0 | AI37: 1 | AJ37: =AI37*(1+AJ31) -> 1 | AK37: =AJ37*(1+AK31) -> 1 | AL37: =AK37*(1+AL31) -> 1 | AM37: =AL37*(1+AM31) -> 1 | AN37: =AM37*(1+AN31) -> 1
C38: IO Periods/Amortization | E38: 0 | F38: =PMT(F36/12,360,-F34,0,) -> 41688.33 | G38: IO Periods/Amortization | H38: 24 | I38: =PMT(I36/12,360,-I34,0,) -> 56150.469 | K38: Millage Rate | M38: 0.018926798 | N38: 0.018926798 | S38: Utilities | U38: =V38*$N$13 -> 0 | V38: 0 | W38: =SUM(OFFSET(F102,0,$G$16,1,-12)) -> 0 | X38: =W38/$N$13 -> 0 | Y38: =SUM(OFFSET(F102,0,$I$16,1,-12)) -> 0 | Z38: =Y38/$N$13 -> 0 | AA38: 0 | AB38: =AA38/$N$13 -> 0 | AC38: 0 | AD38: =AC38/$N$13 -> 0 | AE38: 0 | AF38: =AE38/$N$13 -> 0
C39: Debt Metrics | G39: Debt Metrics | K39: Special Assessment | M39: 0 | N39: 0 | S39: Management Fee | T39: 0.03 | U39: =T39*U25 -> 40721.94 | V39: =U39/N13 -> 646.38 | W39: =SUM(OFFSET(F103,0,$G$16,1,-12)) -> 43396.562 | X39: =W39/$N$13 -> 688.83432 | Y39: =SUM(OFFSET(F103,0,$I$16,1,-12)) -> 50410.175 | Z39: =Y39/$N$13 -> 800.1615 | AA39: 0 | AB39: =AA39/$N$13 -> 0 | AC39: 0 | AD39: =AC39/$N$13 -> 0 | AE39: 0 | AF39: =AE39/$N$13 -> 0
C40: DSCR | F40: =U48/(PMT(6%/12,360,-F34,0)*12) -> 1.7677289 | G40: DSCR | H40: 1.25 | I40: =PV(I36/12,H35,-F17/12/H40) -> 8883611.7 | K40: Total Property Tax | M40: =M35*M38 -> 0 | N40: =N35*N38 -> 0 | S40: Property Tax | U40: =V40*$N$13 -> 44100 | V40: 700 | W40: =SUM(OFFSET(F104,0,$G$16,1,-12)) -> 47591.386 | X40: =W40/$N$13 -> 755.41882 | Y40: =SUM(OFFSET(F104,0,$I$16,1,-12)) -> 55282.952 | Z40: =Y40/$N$13 -> 877.50718 | AA40: 0 | AB40: =AA40/$N$13 -> 0 | AC40: 0 | AD40: =AC40/$N$13 -> 0 | AE40: 0 | AF40: =AE40/$N$13 -> 0
...

Sheet Other Inputs>>

Sheet Pro Forma Template
E1: Mo | F1: =F56 -> 0 | G1: =G56 -> 1 | H1: =H56 -> 2 | I1: =I56 -> 3 | J1: =J56 -> 4 | K1: =K56 -> 5 | L1: =L56 -> 6 | M1: =M56 -> 7 | ... FD1: =FD56 -> 154
E2: Date | F2: =F58 -> 46174 | G2: =G58 -> 46203 | H2: =H58 -> 46234 | I2: =I58 -> 46265 | J2: =J58 -> 46295 | K2: =K58 -> 46326 | L2: =L58 -> 46356 | M2: =M58 -> 46387 | ... FD2: =FD58 -> 50860
C3: Base Assumptions
C4: # | D4: 101 | AN4: Under Construction
C5: Property Name:
C6: Address: | AN6: In Lease Up
C7: Timeline | K7: Income Analysis | S7: ACF Analysis
E8: BOP Mo | F8: BOP Date | G8: Duration | H8: EOP Date | I8: EOP Mo | K8: MR Unit Breakdown | N8: Unit Count | O8: Rent/Unit | P8: Average Size | Q8: Rent PSF | U8: Pro Forma | AA8: Historical Financials
C9: Acquisition Date | E9: 0 | F9: 46174 | G9: 1 | H9: =EOMONTH(F9,E9) -> 46203 | I9: =INDEX($F$56:$FV$56,MATCH(H9,$F$58:$FV$58,0)) -> 1 | K9: Studio | N9: 100 | O9: 2150 | P9: 1000 | Q9: =+O9/P9 -> 2.15 | U9: Untrended | V9: $/Unit | W9: Refinance | X9: $/Unit | Y9: At Exit | Z9: $/Unit | AA9: T-3 | AB9: $/Unit | AC9: T-6 | AD9: $/Unit | AE9: T-12 | AF9: $/Unit
C10: Hold Period | E10: =INDEX($F$56:$FV$56,MATCH(F10,$F$58:$FV$58,0)) -> 2 | F10: =EOMONTH(H9,1) -> 46234 | G10: 36 | H10: =EOMONTH(F10,G10-1) -> 47299 | I10: =INDEX($F$56:$FV$56,MATCH(H10,$F$58:$FV$58,0)) -> 37 | K10: 1 Bedroom | N10: 0 | O10: 0 | P10: 0 | Q10: =IFERROR(+O10/P10,0) -> 0 | S10: Potential Market Rent | U10: =V10*$N$13*12 -> 2580000 | V10: =O13 -> 2150 | W10: =SUM(OFFSET(F74,0,$G$40,1,-12)) -> 2791218.6 | X10: =W10/$N$13 -> 27912.186 | Y10: =SUM(OFFSET(F74,0,$I$40,1,-12)) -> 3234240.8 | Z10: =Y10/$N$13 -> 32342.408 | AA10: 0 | AB10: =AA10/$N$13 -> 0 | AC10: 0 | AD10: =AC10/$N$13 -> 0 | AE10: 0 | AF10: =AE10/$N$13 -> 0
C11: Refinance | E11: =INDEX($F$56:$FV$56,MATCH(F11,$F$58:$FV$58,0)) -> 37 | F11: =EOMONTH(H10,0) -> 47299 | G11: 1 | H11: =EOMONTH(F11,G11-1) -> 47299 | I11: =INDEX($F$56:$FV$56,MATCH(H11,$F$58:$FV$58,0)) -> 37 | K11: 2 Bedroom | N11: 0 | O11: 0 | P11: 0 | Q11: =IFERROR(+O11/P11,0) -> 0 | S11: Loss to Lease | U11: 0 | V11: =U11/$N$13 -> 0 | W11: =SUM(OFFSET(F75,0,$G$40,1,-12)) -> -6978.0465 | X11: =W11/$N$13 -> -69.780465 | Y11: =SUM(OFFSET(F75,0,$I$40,1,-12)) -> -8085.6019 | Z11: =Y11/$N$13 -> -80.856019 | AA11: 0 | AB11: =AA11/$N$13 -> 0 | AC11: 0 | AD11: =AC11/$N$13 -> 0 | AE11: 0 | AF11: =AE11/$N$13 -> 0
C12: Hold Period | D12: 8 | E12: =INDEX($F$56:$FV$56,MATCH(F12,$F$58:$FV$58,0)) -> 38 | F12: =EOMONTH(H11,1) -> 47330 | G12: =I12-E12+1 -> 59 | H12: =EOMONTH(F9,D12*12) -> 49125 | I12: =D12*12 -> 96 | K12: 3 Bedroom | N12: 0 | O12: 0 | P12: 0 | Q12: =IFERROR(+O12/P12,0) -> 0 | S12: Gross Potential Rent | U12: =SUM(U10:U11) -> 2580000 | V12: =SUM(V10:V11) -> 2150 | W12: =SUM(W10:W11) -> 2784240.5 | X12: =W12/$N$13 -> 27842.405 | Y12: =SUM(Y10:Y11) -> 3226155.2 | Z12: =Y12/$N$13 -> 32261.552 | AA12: =SUM(AA10:AA11) -> 0 | AB12: =AA12/$N$13 -> 0 | AC12: =SUM(AC10:AC11) -> 0 | AD12: =AC12/$N$13 -> 0 | AE12: =SUM(AE10:AE11) -> 0 | AF12: =AE12/$N$13 -> 0
K13: Total/Avg (MR+BMR) | N13: =SUM(N9:N12) -> 100 | O13: =SUMPRODUCT(O9:O12,$N$9:$N$12)/$N$13 -> 2150 | P13: =SUMPRODUCT(P9:P12,$N$9:$N$12)/$N$13 -> 1000 | Q13: =SUMPRODUCT(Q9:Q12,$N$9:$N$12)/$N$13 -> 2.15
C14: Project Costs | S14: =K16 -> RUBS | U14: =U38*$N$16 -> 70000 | V14: =U14/$N$13 -> 700 | W14: =SUM(OFFSET(F79,0,$G$40,1,-12)) -> 75730.737 | X14: =W14/$N$13 -> 757.30737 | Y14: =SUM(OFFSET(F79,0,$I$40,1,-12)) -> 87750.718 | Z14: =Y14/$N$13 -> 877.50718 | AA14: 0 | AB14: =AA14/$N$13 -> 0 | AC14: 0 | AD14: =AC14/$N$13 -> 0 | AE14: 0 | AF14: =AE14/$N$13 -> 0
D15: Total Costs | E15: $/Unit | F15: $/RSF | G15: % at Closing | H15: Start Date | I15: Duration | K15: Other Income | N15: % | O15: Count | P15: $ / Unit / Mo | Q15: Annual Total | S15: =K17 -> Parking | U15: =O17*P17*12 -> 0 | V15: =U15/$N$13 -> 0 | W15: =SUM(OFFSET(F80,0,$G$40,1,-12)) -> 0 | X15: =W15/$N$13 -> 0 | Y15: =SUM(OFFSET(F80,0,$I$40,1,-12)) -> 0 | Z15: =Y15/$N$13 -> 0 | AA15: 0 | AB15: =AA15/$N$13 -> 0 | AC15: 0 | AD15: =AC15/$N$13 -> 0 | AE15: 0 | AF15: =AE15/$N$13 -> 0
C16: Acquisition Cost | D16: 25000000 | E16: =D16/$N$13 -> 250000 | F16: =D16/($P$13*$N$13) -> 250 | G16: 1 | H16: =$H$9 -> 46203 | I16: 0 | K16: RUBS | N16: 0.7 | O16: =$N$13 -> 100 | P16: =IFERROR(Q16/O16,0) -> 700 | Q16: =N16*U38 -> 70000 | S16: =K18 -> Other | U16: =Q18 -> 150000 | V16: =U16/$N$13 -> 1500 | W16: =SUM(OFFSET(F81,0,$G$40,1,-12)) -> 162280.15 | X16: =W16/$N$13 -> 1622.8015 | Y16: =SUM(OFFSET(F81,0,$I$40,1,-12)) -> 188037.25 | Z16: =Y16/$N$13 -> 1880.3725 | AA16: 0 | AB16: =AA16/$N$13 -> 0 | AC16: 0 | AD16: =AC16/$N$13 -> 0 | AE16: 0 | AF16: =AE16/$N$13 -> 0
C17: Closing Cost | D17: =D16*1% -> 250000 | E17: =D17/$N$13 -> 2500 | F17: =D17/($P$13*$N$13) -> 2.5 | G17: 1 | H17: =$H$9 -> 46203 | I17: 0 | K17: Parking | O17: =$N$13 -> 100 | P17: 0 | Q17: =P17*O17*12 -> 0 | S17: Total Other Income | U17: =SUM(U14:U16) -> 220000 | V17: =SUM(V14:V16) -> 2200 | W17: =SUM(W14:W16) -> 238010.89 | X17: =W17/$N$13 -> 2380.1089 | Y17: =SUM(Y14:Y16) -> 275787.97 | Z17: =Y17/$N$13 -> 2757.8797 | AA17: =SUM(AA14:AA16) -> 0 | AB17: =AA17/$N$13 -> 0 | AC17: =SUM(AC14:AC16) -> 0 | AD17: =AC17/$N$13 -> 0 | AE17: =SUM(AE14:AE16) -> 0 | AF17: =AE17/$N$13 -> 0
C18: Acquisition Fee | D18: =D16*1% -> 250000 | E18: =D18/$N$13 -> 2500 | F18: =D18/($P$13*$N$13) -> 2.5 | G18: 1 | H18: =$H$9 -> 46203 | I18: 0 | K18: Other | N18: =Q18/U10 -> 0.058139535 | O18: =$N$13 -> 100 | P18: 125 | Q18: =O18*P18*12 -> 150000
C19: Capital Improvements | D19: =E19*N13 -> 1500000 | E19: 15000 | F19: =D19/($P$13*$N$13) -> 15 | G19: 0 | H19: =$H$9 -> 46203 | I19: 12 | K19: Total Other Income | Q19: =SUM(Q16:Q18) -> 220000 | S19: =K23 -> Vacancy Loss | U19: =-SUM($U$12,$U$17)*$M23 -> -140000 | V19: =U19/$N$13 -> -1400 | W19: =SUM(OFFSET(F84,0,$G$40,1,-12)) -> -151112.57 | X19: =W19/$N$13 -> -1511.1257 | Y19: =SUM(OFFSET(F84,0,$I$40,1,-12)) -> -175097.16 | Z19: =Y19/$N$13 -> -1750.9716 | AA19: 0 | AB19: =AA19/$N$13 -> 0 | AC19: 0 | AD19: =AC19/$N$13 -> 0 | AE19: 0 | AF19: =AE19/$N$13 -> 0
C20: Other | D20: =E20*$N$13 -> 0 | E20: 0 | F20: =D20/($P$13*$N$13) -> 0 | G20: 0 | H20: =$H$9 -> 46203 | I20: 0 | S20: =K24 -> Bad Debt | U20: =-SUM($U$12,$U$17)*$M24 -> -7000 | V20: =U20/$N$13 -> -70 | W20: =SUM(OFFSET(F85,0,$G$40,1,-12)) -> -7555.6286 | X20: =W20/$N$13 -> -75.556286 | Y20: =SUM(OFFSET(F85,0,$I$40,1,-12)) -> -8754.8578 | Z20: =Y20/$N$13 -> -87.548578 | AA20: 0 | AB20: =AA20/$N$13 -> 0 | AC20: 0 | AD20: =AC20/$N$13 -> 0 | AE20: 0 | AF20: =AE20/$N$13 -> 0
C21: Other | D21: =E21*$N$13 -> 0 | E21: 0 | F21: =D21/($P$13*$N$13) -> 0 | G21: 0 | H21: =$H$9 -> 46203 | I21: 0 | K21: Income Adjustments | M21: =IF(MONTH(F9)=12,YEAR(F9)+1,YEAR(F9)) -> 2026 | N21: =M21+1 -> 2027 | O21: =N21+1 -> 2028 | P21: =O21+1 -> 2029 | Q21: =P21+1 -> 2030 | S21: =K25 -> Concessions | U21: =-SUM($U$12,$U$17)*$M25 -> -7000 | V21: =U21/$N$13 -> -70 | W21: =SUM(OFFSET(F86,0,$G$40,1,-12)) -> -7555.6286 | X21: =W21/$N$13 -> -75.556286 | Y21: =SUM(OFFSET(F86,0,$I$40,1,-12)) -> -8754.8578 | Z21: =Y21/$N$13 -> -87.548578 | AA21: 0 | AB21: =AA21/$N$13 -> 0 | AC21: 0 | AD21: =AC21/$N$13 -> 0 | AE21: 0 | AF21: =AE21/$N$13 -> 0
C22: Other | D22: 0 | E22: =D22/$N$13 -> 0 | F22: =D22/($P$13*$N$13) -> 0 | G22: 0 | H22: =$H$9 -> 46203 | I22: 0 | K22: Loss to Lease | M22: 0.0025 | N22: 0.0025 | O22: 0.0025 | P22: 0.0025 | Q22: 0.0025 | S22: =K26 -> Model Units | U22: =-O13*M26*12 -> -25800 | V22: =U22/$N$13 -> -258 | W22: =SUM(OFFSET(F87,0,$G$40,1,-12)) -> -27912.186 | X22: =W22/$N$13 -> -279.12186 | Y22: =SUM(OFFSET(F87,0,$I$40,1,-12)) -> -32342.408 | Z22: =Y22/$N$13 -> -323.42408 | AA22: 0 | AB22: =AA22/$N$13 -> 0 | AC22: 0 | AD22: =AC22/$N$13 -> 0 | AE22: 0 | AF22: =AE22/$N$13 -> 0
C23: Total Project Costs | D23: =SUM(D16:D22) -> 27000000 | E23: =D23/$N$13 -> 270000 | F23: =D23/($P$13*$N$13) -> 270 | H23: Cost Schedule | I23: Straight Line | K23: Vacancy Loss | M23: 0.05 | N23: 0.05 | O23: 0.05 | P23: 0.05 | Q23: 0.05 | S23: Total Income Adjustments | U23: =SUM(U19:U22) -> -179800 | V23: =SUM(V19:V22) -> -1798 | W23: =SUM(W19:W22) -> -194136.01 | X23: =W23/$N$13 -> -1941.3601 | Y23: =SUM(Y19:Y22) -> -224949.28 | Z23: =Y23/$N$13 -> -2249.4928 | AA23: =SUM(AA19:AA22) -> 0 | AB23: =AA23/$N$13 -> 0 | AC23: =SUM(AC19:AC22) -> 0 | AD23: =AC23/$N$13 -> 0 | AE23: =SUM(AE19:AE22) -> 0 | AF23: =AE23/$N$13 -> 0
K24: Bad Debt | M24: 0.0025 | N24: 0.0025 | O24: 0.0025 | P24: 0.0025 | Q24: 0.0025
C25: Financing Assumptions | K25: Concessions | M25: 0.0025 | N25: 0.0025 | O25: 0.0025 | P25: 0.0025 | Q25: 0.0025 | S25: EGI | U25: =SUM(U12,U17,U23) -> 2620200 | V25: =SUM(V12,V17,V23) -> 2552 | W25: =SUM(W12,W17,W23) -> 2828115.4 | X25: =SUM(X12,X17,X23) -> 28281.154 | Y25: =SUM(Y12,Y17,Y23) -> 3276993.8 | Z25: =SUM(Z12,Z17,Z23) -> 32769.938 | AA25: =SUM(AA12,AA17,AA23) -> 0 | AB25: =SUM(AB12,AB17,AB23) -> 0 | ... AF25: =SUM(AF12,AF17,AF23) -> 0
C26: Senior Financing | E26: Senior Financing | H26: Refinance | K26: Model Units | M26: 1 | N26: 1 | O26: 1 | P26: 1 | Q26: 1
C27: Lender | F27: TBD | G27: Lender | I27: TBD | K27: Growth Assumptions | M27: =IF(MONTH(F9)=12,YEAR(F9)+1,YEAR(F9)) -> 2026 | N27: =M27+1 -> 2027 | O27: =N27+1 -> 2028 | P27: =O27+1 -> 2029 | Q27: =P27+1 -> 2030 | S27: Opex
C28: Loan Proceeds | E28: 0.55 | F28: =E28*$D$23 -> 14850000 | G28: Loan Proceeds | H28: DSCR | I28: =INDEX($I$34:$I$36,MATCH(H28,$G$34:$G$36,0)) -> 21662073 | K28: Market Rent | M28: 0.03 | N28: 0.03 | O28: 0.03 | P28: 0.03 | Q28: 0.03 | S28: Payroll | U28: =V28*$N$13 -> 150000 | V28: 1500 | W28: =SUM(OFFSET(F94,0,$G$40,1,-12)) -> 162280.15 | X28: =W28/$N$13 -> 1622.8015 | Y28: =SUM(OFFSET(F94,0,$I$40,1,-12)) -> 188037.25 | Z28: =Y28/$N$13 -> 1880.3725 | AA28: 0 | AB28: =AA28/$N$13 -> 0 | AC28: 0 | AD28: =AC28/$N$13 -> 0 | AE28: 0 | AF28: =AE28/$N$13 -> 0
C29: Term | E29: 36 | F29: =EOMONTH(F9,E29) -> 47299 | G29: Term | H29: 360 | I29: =EOMONTH(F29,H29-1) -> 58226 | K29: Other Income | M29: 0.03 | N29: 0.03 | O29: 0.03 | P29: 0.03 | Q29: 0.03 | S29: Admin | U29: =V29*$N$13 -> 30000 | V29: 300 | W29: =SUM(OFFSET(F95,0,$G$40,1,-12)) -> 32456.03 | X29: =W29/$N$13 -> 324.5603 | Y29: =SUM(OFFSET(F95,0,$I$40,1,-12)) -> 37607.451 | Z29: =Y29/$N$13 -> 376.07451 | AA29: 0 | AB29: =AA29/$N$13 -> 0 | AC29: 0 | AD29: =AC29/$N$13 -> 0 | AE29: 0 | AF29: =AE29/$N$13 -> 0
C30: Interest Rate | E30: Fixed | F30: 0.07 | G30: Interest Rate | H30: Fixed | I30: 0.06 | K30: Operating Expenses | M30: 0.03 | N30: 0.03 | O30: 0.03 | P30: 0.03 | Q30: 0.03 | S30: Marketing | U30: =V30*$N$13 -> 30000 | V30: 300 | W30: =SUM(OFFSET(F96,0,$G$40,1,-12)) -> 32456.03 | X30: =W30/$N$13 -> 324.5603 | Y30: =SUM(OFFSET(F96,0,$I$40,1,-12)) -> 37607.451 | Z30: =Y30/$N$13 -> 376.07451 | AA30: 0 | AB30: =AA30/$N$13 -> 0 | AC30: 0 | AD30: =AC30/$N$13 -> 0 | AE30: 0 | AF30: =AE30/$N$13 -> 0
C31: Financing Costs | E31: 0.01 | F31: =E31*F28 -> 148500 | G31: Financing Costs | H31: 0.005 | I31: =H31*I28 -> 108310.36 | K31: Property Taxes | M31: 0.03 | N31: 0.03 | O31: 0.03 | P31: 0.03 | Q31: 0.03 | S31: R&M | U31: =V31*$N$13 -> 30000 | V31: 300 | W31: =SUM(OFFSET(F97,0,$G$40,1,-12)) -> 32456.03 | X31: =W31/$N$13 -> 324.5603 | Y31: =SUM(OFFSET(F97,0,$I$40,1,-12)) -> 37607.451 | Z31: =Y31/$N$13 -> 376.07451 | AA31: 0 | AB31: =AA31/$N$13 -> 0 | AC31: 0 | AD31: =AC31/$N$13 -> 0 | AE31: 0 | AF31: =AE31/$N$13 -> 0
C32: IO Periods/Amortization | E32: 24 | F32: =PMT(F30/12,360,-F28,0,) -> 98797.421 | G32: IO Periods/Amortization | H32: 24 | I32: =PMT(I30/12,360,-I28,0,) -> 129875.07 | S32: Contract Service | U32: =V32*$N$13 -> 30000 | V32: 300 | W32: =SUM(OFFSET(F98,0,$G$40,1,-12)) -> 32456.03 | X32: =W32/$N$13 -> 324.5603 | Y32: =SUM(OFFSET(F98,0,$I$40,1,-12)) -> 37607.451 | Z32: =Y32/$N$13 -> 376.07451 | AA32: 0 | AB32: =AA32/$N$13 -> 0 | AC32: 0 | AD32: =AC32/$N$13 -> 0 | AE32: 0 | AF32: =AE32/$N$13 -> 0
C33: Debt Metrics | G33: Debt Metrics | K33: Property Taxes | S33: Turnover | U33: =V33*$N$13 -> 30000 | V33: 300 | W33: =SUM(OFFSET(F99,0,$G$40,1,-12)) -> 32456.03 | X33: =W33/$N$13 -> 324.5603 | Y33: =SUM(OFFSET(F99,0,$I$40,1,-12)) -> 37607.451 | Z33: =Y33/$N$13 -> 376.07451 | AA33: 0 | AB33: =AA33/$N$13 -> 0 | AC33: 0 | AD33: =AC33/$N$13 -> 0 | AE33: 0 | AF33: =AE33/$N$13 -> 0
C34: DSCR | F34: =U48/(PMT(6%/12,360,-F28,0)*12) -> 1.6909589 | G34: DSCR | H34: 1.25 | I34: =PV(I30/12,H29,-F41/12/H34) -> 21662073 | M34: Current | N34: Next Buyer | O34: Note | S34: Other | U34: =V34*$N$13 -> 0 | V34: 0 | W34: =SUM(OFFSET(F100,0,$G$40,1,-12)) -> 0 | X34: =W34/$N$13 -> 0 | Y34: =SUM(OFFSET(F100,0,$I$40,1,-12)) -> 0 | Z34: =Y34/$N$13 -> 0 | AA34: 0 | AB34: =AA34/$N$13 -> 0 | AC34: 0 | AD34: =AC34/$N$13 -> 0 | AE34: 0 | AF34: =AE34/$N$13 -> 0
C35: DY | F35: =U48/F28 -> 0.12165783 | G35: DY | H35: 0.08 | I35: =F41/H35 -> 24351576 | K35: Assessed Value | M35: =M36*N13 -> 14000000 | N35: =N36*N13 -> 14000000 | S35: Total Controllable Expenses | U35: =SUM(U28:U34) -> 300000 | V35: =SUM(V28:V34) -> 3000 | W35: =SUM(W28:W34) -> 324560.3 | X35: =SUM(X28:X34) -> 3245.603 | Y35: =SUM(Y28:Y34) -> 376074.51 | Z35: =SUM(Z28:Z34) -> 3760.7451 | AA35: =SUM(AA28:AA34) -> 0 | AB35: =AA35/$N$13 -> 0 | AC35: =SUM(AC28:AC34) -> 0 | AD35: =AC35/$N$13 -> 0 | AE35: =SUM(AE28:AE34) -> 0 | AF35: =AE35/$N$13 -> 0
C36: LTV | G36: LTV | H36: 0.75 | I36: =H36*F45 -> 25410340 | K36: Assessed Value/Unit | M36: 140000 | N36: =M36 -> 140000
K37: Assessment % | M37: 1 | N37: =M37 -> 1 | S37: Insurance | U37: =V37*$N$13 -> 50000 | V37: 500 | W37: =SUM(OFFSET(F104,0,$G$40,1,-12)) -> 54093.384 | X37: =W37/$N$13 -> 540.93384 | Y37: =SUM(OFFSET(F104,0,$I$40,1,-12)) -> 62679.084 | Z37: =Y37/$N$13 -> 626.79084 | AA37: 0 | AB37: =AA37/$N$13 -> 0 | AC37: 0 | AD37: =AC37/$N$13 -> 0 | AE37: 0 | AF37: =AE37/$N$13 -> 0 | AI37: 1 | AJ37: =AI37*(1+AJ31) -> 1 | AK37: =AJ37*(1+AK31) -> 1 | AL37: =AK37*(1+AL31) -> 1 | AM37: =AL37*(1+AM31) -> 1 | AN37: =AM37*(1+AN31) -> 1
C38: Residual Analysis | K38: Millage Rate | M38: 0.018926798 | N38: 0.018926798 | S38: Utilities | U38: =V38*$N$13 -> 100000 | V38: 1000 | W38: =SUM(OFFSET(F105,0,$G$40,1,-12)) -> 108186.77 | X38: =W38/$N$13 -> 1081.8677 | Y38: =SUM(OFFSET(F105,0,$I$40,1,-12)) -> 125358.17 | Z38: =Y38/$N$13 -> 1253.5817 | AA38: 0 | AB38: =AA38/$N$13 -> 0 | AC38: 0 | AD38: =AC38/$N$13 -> 0 | AE38: 0 | AF38: =AE38/$N$13 -> 0
F39: Refinance | G39: $/Unit | H39: Exit | I39: $/Unit | K39: Special Assessment | M39: 0 | N39: 0 | S39: Management Fee | T39: 0.03 | U39: =T39*U25 -> 78606 | V39: =U39/N13 -> 786.06 | W39: =SUM(OFFSET(F106,0,$G$40,1,-12)) -> 84843.463 | X39: =W39/$N$13 -> 848.43463 | Y39: =SUM(OFFSET(F106,0,$I$40,1,-12)) -> 98309.815 | Z39: =Y39/$N$13 -> 983.09815 | AA39: 0 | AB39: =AA39/$N$13 -> 0 | AC39: 0 | AD39: =AC39/$N$13 -> 0 | AE39: 0 | AF39: =AE39/$N$13 -> 0
C40: Date | Month | F40: =F11 -> 47299 | G40: =E11 -> 37 | H40: =H12 -> 49125 | I40: =I12 -> 96 | K40: Total Property Tax | M40: =M35*M38 -> 264975.17 | N40: =N35*N38 -> 264975.17 | S40: Property Tax | U40: =V40*$N$13 -> 264975.17 | V40: =N41 -> 2649.7517 | W40: =SUM(OFFSET(F107,0,$G$40,1,-12)) -> 286668.07 | X40: =W40/$N$13 -> 2866.6807 | Y40: =SUM(OFFSET(F107,0,$I$40,1,-12)) -> 332168.02 | Z40: =Y40/$N$13 -> 3321.6802 | AA40: 0 | AB40: =AA40/$N$13 -> 0 | AC40: 0 | AD40: =AC40/$N$13 -> 0 | AE40: 0 | AF40: =AE40/$N$13 -> 0
...

Sheet SOFR
B2: EOM | C2: Date | D2: 1 Month Term SOFR Forward Curve
B3: =EOMONTH(C3,0) -> 46081 | C3: 46070 | D3: 0.0366293
B4: =EOMONTH(C4,0) -> 46112 | C4: 46098 | D4: 0.0365167
B5: =EOMONTH(C5,0) -> 46142 | C5: 46129 | D5: 0.0361732
B6: =EOMONTH(C6,0) -> 46173 | C6: 46160 | D6: 0.0357834
B7: =EOMONTH(C7,0) -> 46203 | C7: 46190 | D7: 0.0349209
B8: =EOMONTH(C8,0) -> 46234 | C8: 46220 | D8: 0.0341197
B9: =EOMONTH(C9,0) -> 46265 | C9: 46251 | D9: 0.0334921
B10: =EOMONTH(C10,0) -> 46295 | C10: 46282 | D10: 0.0319517
B11: =EOMONTH(C11,0) -> 46326 | C11: 46314 | D11: 0.0319503
B12: =EOMONTH(C12,0) -> 46356 | C12: 46343 | D12: 0.0319137
B13: =EOMONTH(C13,0) -> 46387 | C13: 46373 | D13: 0.0308998
B14: =EOMONTH(C14,0) -> 46418 | C14: 46406 | D14: 0.0308972
... B123: =EOMONTH(C123,0) -> 49734 | C123: 49724 | D123: 0.0428121

Sheet Exclude ->

Sheet Cost Curve
B2: Construction Cost Curve
B3: Month | C3: 1 | D3: =C3+1 -> 2 | E3: =D3+1 -> 3 | F3: =E3+1 -> 4 | G3: =F3+1 -> 5 | H3: =G3+1 -> 6 | I3: =H3+1 -> 7 | J3: =I3+1 -> 8 | K3: =J3+1 -> 9 | ... AL3: =AK3+1 -> 36
B4: =B5-1 -> 1 | C4: 1
B5: =B6-1 -> 2 | C5: 0.5 | D5: 0.5
B6: =B7-1 -> 3 | C6: 0.33333333 | D6: 0.33333333 | E6: 0.33333333
B7: =B8-1 -> 4 | C7: 0.2 | D7: 0.3 | E7: 0.3 | F7: 0.2
B8: =B9-1 -> 5 | C8: 0.15 | D8: 0.2 | E8: 0.3 | F8: 0.2 | G8: 0.15
B9: =B10-1 -> 6 | C9: 0.1 | D9: 0.15 | E9: 0.25 | F9: 0.25 | G9: 0.15 | H9: 0.1
B10: =B11-1 -> 7 | C10: 0.075 | D10: 0.125 | E10: 0.175 | F10: 0.25 | G10: 0.175 | H10: 0.125 | I10: 0.075
B11: =B12-1 -> 8 | C11: 0.05 | D11: 0.1 | E11: 0.15 | F11: 0.2 | G11: 0.2 | H11: 0.15 | I11: 0.1 | J11: 0.05
B12: =B13-1 -> 9 | C12: 0.05 | D12: 0.075 | E12: 0.125 | F12: 0.15 | G12: 0.2 | H12: 0.15 | I12: 0.125 | J12: 0.075 | K12: 0.05
B13: 10 | C13: 0.04 | D13: 0.065 | E13: 0.1 | F13: 0.125 | G13: 0.17 | H13: 0.17 | I13: 0.125 | J13: 0.1 | K13: 0.065 | L13: 0.04
B14: 11 | C14: 0.035 | D14: 0.05 | E14: 0.09 | F14: 0.12 | G14: 0.13 | H14: 0.15 | I14: 0.13 | J14: 0.12 | K14: 0.09 | L14: 0.05 | M14: 0.035
B15: 12 | C15: 0.03 | D15: 0.05 | E15: 0.07 | F15: 0.1 | G15: 0.12 | H15: 0.13 | I15: 0.13 | J15: 0.12 | K15: 0.1 | L15: 0.07 | M15: 0.05 | N15: 0.03
B16: =+B15+1 -> 13 | C16: 0.025 | D16: 0.04 | E16: 0.06 | F16: 0.09 | G16: 0.11 | H16: 0.11 | I16: 0.13 | J16: 0.11 | K16: 0.11 | L16: 0.09 | M16: 0.06 | N16: 0.04 | O16: 0.025
B17: =+B16+1 -> 14 | C17: 0.02 | D17: 0.04 | E17: 0.06 | F17: 0.08 | G17: 0.08 | H17: 0.1 | I17: 0.12 | J17: 0.12 | K17: 0.1 | L17: 0.08 | M17: 0.08 | N17: 0.06 | O17: 0.04 | P17: 0.02
B18: =+B17+1 -> 15 | C18: 0.02 | D18: 0.03 | E18: 0.05 | F18: 0.07 | G18: 0.08 | H18: 0.09 | I18: 0.1 | J18: 0.12 | K18: 0.1 | L18: 0.09 | M18: 0.08 | N18: 0.07 | O18: 0.05 | P18: 0.03 | Q18: 0.02
B19: =+B18+1 -> 16 | C19: 0.02 | D19: 0.03 | E19: 0.05 | F19: 0.06 | G19: 0.07 | H19: 0.08 | I19: 0.09 | J19: 0.1 | K19: 0.1 | L19: 0.09 | M19: 0.08 | N19: 0.07 | O19: 0.06 | P19: 0.05 | Q19: 0.03 | R19: 0.02
B20: =+B19+1 -> 17 | C20: 0.02 | D20: 0.03 | E20: 0.04 | F20: 0.05 | G20: 0.06 | H20: 0.07 | I20: 0.09 | J20: 0.09 | K20: 0.1 | L20: 0.09 | M20: 0.09 | N20: 0.07 | O20: 0.06 | P20: 0.05 | Q20: 0.04 | R20: 0.03 | S20: 0.02
B21: =+B20+1 -> 18 | C21: 0.015 | D21: 0.025 | E21: 0.025 | F21: 0.025 | G21: 0.03 | H21: 0.04 | I21: 0.05 | J21: 0.08 | K21: 0.1 | L21: 0.1 | M21: 0.08 | N21: 0.08 | O21: 0.08 | P21: 0.08 | Q21: 0.08 | R21: 0.06 | S21: 0.03 | T21: 0.02
B22: =+B21+1 -> 19 | C22: 0.015 | D22: 0.025 | E22: 0.025 | F22: 0.025 | G22: 0.025 | H22: 0.03 | I22: 0.05 | J22: 0.065 | K22: 0.08 | L22: 0.08 | M22: 0.08 | N22: 0.08 | O22: 0.08 | P22: 0.08 | Q22: 0.08 | R22: 0.08 | S22: 0.06 | T22: 0.03 | U22: 0.01
B23: =+B22+1 -> 20 | C23: 0.015 | D23: 0.015 | E23: 0.025 | F23: 0.025 | G23: 0.03 | H23: 0.03 | I23: 0.04 | J23: 0.05 | K23: 0.07 | L23: 0.07 | M23: 0.08 | N23: 0.08 | O23: 0.08 | P23: 0.08 | Q23: 0.08 | R23: 0.08 | S23: 0.07 | T23: 0.05 | U23: 0.02 | V23: 0.01
B24: =+B23+1 -> 21 | C24: 0.01 | D24: 0.01 | E24: 0.02 | F24: 0.02 | G24: 0.02 | H24: 0.03 | I24: 0.04 | J24: 0.05 | K24: 0.07 | L24: 0.07 | M24: 0.07 | N24: 0.08 | O24: 0.08 | P24: 0.08 | Q24: 0.08 | R24: 0.08 | S24: 0.08 | T24: 0.05 | U24: 0.03 | V24: 0.02 | W24: 0.01
B25: =+B24+1 -> 22 | C25: 0.01 | D25: 0.01 | E25: 0.01 | F25: 0.02 | G25: 0.02 | H25: 0.02 | I25: 0.03 | J25: 0.04 | K25: 0.05 | L25: 0.07 | M25: 0.07 | N25: 0.08 | O25: 0.08 | P25: 0.08 | Q25: 0.08 | R25: 0.08 | S25: 0.08 | T25: 0.08 | U25: 0.05 | V25: 0.02 | W25: 0.01 | X25: 0.01
B26: =+B25+1 -> 23 | C26: 0.01 | D26: 0.01 | E26: 0.01 | F26: 0.01 | G26: 0.02 | H26: 0.02 | I26: 0.02 | J26: 0.03 | K26: 0.04 | L26: 0.06 | M26: 0.07 | N26: 0.07 | O26: 0.08 | P26: 0.08 | Q26: 0.08 | R26: 0.08 | S26: 0.08 | T26: 0.08 | U26: 0.06 | V26: 0.03 | W26: 0.03 | X26: 0.02 | Y26: 0.01
B27: =+B26+1 -> 24 | C27: 0.01 | D27: 0.01 | E27: 0.01 | F27: 0.01 | G27: 0.01 | H27: 0.02 | I27: 0.02 | J27: 0.02 | K27: 0.03 | L27: 0.05 | M27: 0.06 | N27: 0.07 | O27: 0.07 | P27: 0.08 | Q27: 0.08 | R27: 0.08 | S27: 0.08 | T27: 0.08 | U27: 0.08 | V27: 0.05 | W27: 0.03 | X27: 0.02 | Y27: 0.02 | Z27: 0.01
B28: =+B27+1 -> 25 | C28: 0.0032051282 | D28: 0.0096153846 | E28: 0.016025641 | F28: 0.022435897 | G28: 0.028846154 | H28: 0.03525641 | I28: 0.041666667 | J28: 0.048076923 | K28: 0.054487179 | L28: 0.060897436 | M28: 0.067307692 | N28: 0.073717949 | O28: 0.076923077 | P28: 0.073717949 | Q28: 0.067307692 | R28: 0.060897436 | S28: 0.054487179 | T28: 0.048076923 | U28: 0.041666667 | V28: 0.03525641 | W28: 0.028846154 | X28: 0.022435897 | Y28: 0.016025641 | Z28: 0.0096153846 | AA28: 0.0032051282
B29: =+B28+1 -> 26 | C29: 0.0054945055 | D29: 0.010989011 | E29: 0.016483516 | F29: 0.021978022 | G29: 0.027472527 | H29: 0.032967033 | I29: 0.038461538 | J29: 0.043956044 | K29: 0.049450549 | L29: 0.054945055 | M29: 0.06043956 | N29: 0.065934066 | O29: 0.071428571 | P29: 0.071428571 | Q29: 0.065934066 | R29: 0.06043956 | S29: 0.054945055 | T29: 0.049450549 | U29: 0.043956044 | V29: 0.038461538 | W29: 0.032967033 | X29: 0.027472527 | Y29: 0.021978022 | Z29: 0.016483516 | AA29: 0.010989011 | AB29: 0.0054945055
B30: =+B29+1 -> 27 | C30: 0.0027472527 | D30: 0.0082417582 | E30: 0.013736264 | F30: 0.019230769 | G30: 0.024725275 | H30: 0.03021978 | I30: 0.035714286 | J30: 0.041208791 | K30: 0.046703297 | L30: 0.052197802 | M30: 0.057692308 | N30: 0.063186813 | O30: 0.068681319 | P30: 0.071428571 | Q30: 0.068681319 | R30: 0.063186813 | S30: 0.057692308 | T30: 0.052197802 | U30: 0.046703297 | V30: 0.041208791 | W30: 0.035714286 | X30: 0.03021978 | Y30: 0.024725275 | Z30: 0.019230769 | AA30: 0.013736264 | AB30: 0.0082417582 | AC30: 0.0027472527
B31: =+B30+1 -> 28 | C31: 0.0047619048 | D31: 0.0095238095 | E31: 0.014285714 | F31: 0.019047619 | G31: 0.023809524 | H31: 0.028571429 | I31: 0.033333333 | J31: 0.038095238 | K31: 0.042857143 | L31: 0.047619048 | M31: 0.052380952 | N31: 0.057142857 | O31: 0.061904762 | P31: 0.066666667 | Q31: 0.066666667 | R31: 0.061904762 | S31: 0.057142857 | T31: 0.052380952 | U31: 0.047619048 | V31: 0.042857143 | W31: 0.038095238 | X31: 0.033333333 | Y31: 0.028571429 | Z31: 0.023809524 | AA31: 0.019047619 | AB31: 0.014285714 | AC31: 0.0095238095 | AD31: 0.0047619048
B32: =+B31+1 -> 29 | C32: 0.0023809524 | D32: 0.0071428571 | E32: 0.011904762 | F32: 0.016666667 | G32: 0.021428571 | H32: 0.026190476 | I32: 0.030952381 | J32: 0.035714286 | K32: 0.04047619 | L32: 0.045238095 | M32: 0.05 | N32: 0.054761905 | O32: 0.05952381 | P32: 0.064285714 | Q32: 0.066666667 | R32: 0.064285714 | S32: 0.05952381 | T32: 0.054761905 | U32: 0.05 | V32: 0.045238095 | W32: 0.04047619 | X32: 0.035714286 | Y32: 0.030952381 | Z32: 0.026190476 | AA32: 0.021428571 | AB32: 0.016666667 | AC32: 0.011904762 | AD32: 0.0071428571 | AE32: 0.0023809524
B33: =+B32+1 -> 30 | C33: 0.0041666667 | D33: 0.0083333333 | E33: 0.0125 | F33: 0.016666667 | G33: 0.020833333 | H33: 0.025 | I33: 0.029166667 | J33: 0.033333333 | K33: 0.0375 | L33: 0.041666667 | M33: 0.045833333 | N33: 0.05 | O33: 0.054166667 | P33: 0.058333333 | Q33: 0.0625 | R33: 0.0625 | S33: 0.058333333 | T33: 0.054166667 | U33: 0.05 | V33: 0.045833333 | W33: 0.041666667 | X33: 0.0375 | Y33: 0.033333333 | Z33: 0.029166667 | AA33: 0.025 | AB33: 0.020833333 | AC33: 0.016666667 | AD33: 0.0125 | AE33: 0.0083333333 | AF33: 0.0041666667
B34: =+B33+1 -> 31 | C34: 0.0020833333 | D34: 0.00625 | E34: 0.010416667 | F34: 0.014583333 | G34: 0.01875 | H34: 0.022916667 | I34: 0.027083333 | J34: 0.03125 | K34: 0.035416667 | L34: 0.039583333 | M34: 0.04375 | N34: 0.047916667 | O34: 0.052083333 | P34: 0.05625 | Q34: 0.060416667 | R34: 0.0625 | S34: 0.060416667 | T34: 0.05625 | U34: 0.052083333 | V34: 0.047916667 | W34: 0.04375 | X34: 0.039583333 | Y34: 0.035416667 | Z34: 0.03125 | AA34: 0.027083333 | AB34: 0.022916667 | AC34: 0.01875 | AD34: 0.014583333 | AE34: 0.010416667 | AF34: 0.00625 | AG34: 0.0020833333
B35: =+B34+1 -> 32 | C35: 0.0036764706 | D35: 0.0073529412 | E35: 0.011029412 | F35: 0.014705882 | G35: 0.018382353 | H35: 0.022058824 | I35: 0.025735294 | J35: 0.029411765 | K35: 0.033088235 | L35: 0.036764706 | M35: 0.040441176 | N35: 0.044117647 | O35: 0.047794118 | P35: 0.051470588 | Q35: 0.055147059 | R35: 0.058823529 | S35: 0.058823529 | T35: 0.055147059 | U35: 0.051470588 | V35: 0.047794118 | W35: 0.044117647 | X35: 0.040441176 | Y35: 0.036764706 | Z35: 0.033088235 | AA35: 0.029411765 | AB35: 0.025735294 | AC35: 0.022058824 | AD35: 0.018382353 | AE35: 0.014705882 | AF35: 0.011029412 | AG35: 0.0073529412 | AH35: 0.0036764706
B36: =+B35+1 -> 33 | C36: 0.0018382353 | D36: 0.0055147059 | E36: 0.0091911765 | F36: 0.012867647 | G36: 0.016544118 | H36: 0.020220588 | I36: 0.023897059 | J36: 0.027573529 | K36: 0.03125 | L36: 0.034926471 | M36: 0.038602941 | N36: 0.042279412 | O36: 0.045955882 | P36: 0.049632353 | Q36: 0.053308824 | R36: 0.056985294 | S36: 0.058823529 | T36: 0.056985294 | U36: 0.053308824 | V36: 0.049632353 | W36: 0.045955882 | X36: 0.042279412 | Y36: 0.038602941 | Z36: 0.034926471 | AA36: 0.03125 | AB36: 0.027573529 | AC36: 0.023897059 | AD36: 0.020220588 | AE36: 0.016544118 | AF36: 0.012867647 | AG36: 0.0091911765 | AH36: 0.0055147059 | AI36: 0.0018382353
B37: =+B36+1 -> 34 | C37: 0.0032679739 | D37: 0.0065359477 | E37: 0.0098039216 | F37: 0.013071895 | G37: 0.016339869 | H37: 0.019607843 | I37: 0.022875817 | J37: 0.026143791 | K37: 0.029411765 | L37: 0.032679739 | M37: 0.035947712 | N37: 0.039215686 | O37: 0.04248366 | P37: 0.045751634 | Q37: 0.049019608 | R37: 0.052287582 | S37: 0.055555556 | T37: 0.055555556 | U37: 0.052287582 | V37: 0.049019608 | W37: 0.045751634 | X37: 0.04248366 | Y37: 0.039215686 | Z37: 0.035947712 | AA37: 0.032679739 | AB37: 0.029411765 | AC37: 0.026143791 | AD37: 0.022875817 | AE37: 0.019607843 | AF37: 0.016339869 | AG37: 0.013071895 | AH37: 0.0098039216 | AI37: 0.0065359477 | AJ37: 0.0032679739
B38: =+B37+1 -> 35 | C38: 0.0016339869 | D38: 0.0049019608 | E38: 0.0081699346 | F38: 0.011437908 | G38: 0.014705882 | H38: 0.017973856 | I38: 0.02124183 | J38: 0.024509804 | K38: 0.027777778 | L38: 0.031045752 | M38: 0.034313725 | N38: 0.037581699 | O38: 0.040849673 | P38: 0.044117647 | Q38: 0.047385621 | R38: 0.050653595 | S38: 0.053921569 | T38: 0.055555556 | U38: 0.053921569 | V38: 0.050653595 | W38: 0.047385621 | X38: 0.044117647 | Y38: 0.040849673 | Z38: 0.037581699 | AA38: 0.034313725 | AB38: 0.031045752 | AC38: 0.027777778 | AD38: 0.024509804 | AE38: 0.02124183 | AF38: 0.017973856 | AG38: 0.014705882 | AH38: 0.011437908 | AI38: 0.0081699346 | AJ38: 0.0049019608 | AK38: 0.0016339869
B39: =+B38+1 -> 36 | C39: 0.0029239766 | D39: 0.0058479532 | E39: 0.0087719298 | F39: 0.011695906 | G39: 0.014619883 | H39: 0.01754386 | I39: 0.020467836 | J39: 0.023391813 | K39: 0.026315789 | L39: 0.029239766 | M39: 0.032163743 | N39: 0.035087719 | O39: 0.038011696 | P39: 0.040935673 | Q39: 0.043859649 | R39: 0.046783626 | S39: 0.049707602 | T39: 0.052631579 | U39: 0.052631579 | V39: 0.049707602 | W39: 0.046783626 | X39: 0.043859649 | Y39: 0.040935673 | Z39: 0.038011696 | AA39: 0.035087719 | AB39: 0.032163743 | AC39: 0.029239766 | AD39: 0.026315789 | AE39: 0.023391813 | AF39: 0.020467836 | AG39: 0.01754386 | AH39: 0.014619883 | AI39: 0.011695906 | AJ39: 0.0087719298 | AK39: 0.0058479532 | AL39: 0.0029239766
C41: 43281 | D41: 43312 | E41: 43343 | F41: 43373 | G41: 43404 | H41: 43434 | I41: 43465 | J41: 43496 | K41: 43524 | L41: 43555 | M41: 43585 | N41: 43616 | O41: 43646 | P41: 43677 | Q41: 43708 | R41: 43738 | S41: 43769 | T41: 43799 | U41: 43830 | V41: 43861 | W41: 43890 | X41: 43921 | Y41: 43951 | Z41: 43982 | AA41: 44012 | AB41: 44043 | AC41: 44074 | AD41: 44104 | AE41: 44135 | AF41: 44165 | AG41: 44196 | AH41: 44227 | AI41: 44255 | AJ41: 44286 | AK41: 44316 | AL41: 44347 | AM41: 44377 | AN41: 44408 | AO41: 44439 | AP41: 44469 | AQ41: 44500 | AR41: 44530 | AS41: 44561 | AT41: 44592 | AU41: 44620 | AV41: 44651 | AW41: 44681 | AX41: 44712 | AY41: 44742 | AZ41: 44773 | BA41: 44804 | BB41: 44834 | BC41: 44865 | BD41: 44895 | BE41: 44926 | BF41: 44957 | BG41: 44985 | BH41: 45016 | BI41: 45046 | BJ41: 45077 | BK41: 45107 | BL41: 45138 | BM41: 45169 | BN41: 45199 | BO41: 45230 | BP41: 45260 | BQ41: 45291 | BR41: 45322 | BS41: 45351 | BT41: 45382 | BU41: 45412 | BV41: 45443 | BW41: 45473 | BX41: 45504 | BY41: 45535 | BZ41: 45565 | CA41: 45596 | CB41: 45626 | CC41: 45657 | CD41: 45688 | CE41: 45716 | CF41: 45747 | CG41: 45777 | CH41: 45808 | CI41: 45838 | CJ41: 45869 | CK41: 45900 | CL41: 45930 | CM41: 45961 | CN41: 45991 | CO41: 46022 | CP41: 46053 | CQ41: 46081 | CR41: 46112 | CS41: 46142 | CT41: 46173 | CU41: 46203 | CV41: 46234 | CW41: 46265 | CX41: 46295 | CY41: 46326 | CZ41: 46356 | DA41: 46387 | DB41: 46418 | DC41: 46446 | DD41: 46477 | DE41: 46507 | DF41: 46538 | DG41: 46568 | DH41: 46599 | DI41: 46630 | DJ41: 46660 | DK41: 46691 | DL41: 46721 | DM41: 46752 | DN41: 46783 | DO41: 46812 | DP41: 46843 | DQ41: 46873 | DR41: 46904 | DS41: 46934 | DT41: 46965 | DU41: 46996 | DV41: 47026 | DW41: 47057 | DX41: 47087 | DY41: 47118 | DZ41: 47149 | EA41: 47177 | EB41: 47208 | EC41: 47238 | ED41: 47269 | EE41: 47299 | EF41: 47330 | EG41: 47361 | EH41: 47391 | EI41: 47422 | EJ41: 47452 | EK41: 47483 | EL41: 47514 | EM41: 47542 | EN41: 47573 | EO41: 47603 | EP41: 47634 | EQ41: 47664 | ER41: 47695 | ES41: 47726 | ET41: 47756 | EU41: 47787 | EV41: 47817 | EW41: 47848 | EX41: 47879 | EY41: 47907 | EZ41: 47938 | FA41: 47968 | FB41: 47999 | FC41: 48029 | FD41: 48060 | FE41: 48091 | FF41: 48121 | FG41: 48152 | FH41: 48182 | FI41: 48213 | FJ41: 48244 | FK41: 48273 | FL41: 48304 | FM41: 48334 | FN41: 48365 | FO41: 48395 | FP41: 48426 | FQ41: 48457 | FR41: 48487 | FS41: 48518 | FT41: 48548 | FU41: 48579 | FV41: 48610 | FW41: 48638 | FX41: 48669 | FY41: 48699 | FZ41: 48730 | GA41: 48760 | GB41: 48791 | GC41: 48822 | GD41: 48852 | GE41: 48883 | GF41: 48913 | GG41: 48944 | GH41: 48975 | GI41: 49003 | GJ41: 49034 | GK41: 49064 | GL41: 49095 | GM41: 49125
B42: LIBOR Curve | C42: 0.0209025 | D42: 0.0208138 | E42: 0.0211375 | F42: 0.0226056 | G42: 0.0230688 | H42: 0.0234694 | I42: 0.0250269 | J42: 0.0251375 | K42: 0.0249038 | L42: 0.024945 | M42: 0.024805 | N42: 0.024305 | O42: 0.02398 | P42: 0.0222425 | Q42: 0.02089 | R42: 0.0201563 | S42: 0.0178488 | T42: 0.0169713 | U42: 0.017625 | V42: 0.0166188 | W42: 0.0151525 | X42: 0.0113625 | Y42: 0.0101245 | Z42: 0.0091342 | AA42: 0.0084722 | AB42: 0.0079368 | AC42: 0.0074057 | AD42: 0.0069192 | AE42: 0.0066086 | AF42: 0.0064933 | AG42: 0.0065614 | AH42: 0.0066812 | AI42: 0.0067386 | AJ42: 0.0067482 | AK42: 0.0067406 | AL42: 0.0067174 | AM42: 0.0067187 | AN42: 0.0067521 | AO42: 0.0067961 | AP42: 0.0068751 | AQ42: 0.0069825 | AR42: 0.0070909 | AS42: 0.0072186 | AT42: 0.0073642 | AU42: 0.0075058 | AV42: 0.0076563 | AW42: 0.0078098 | AX42: 0.0079447 | AY42: 0.0080764 | AZ42: 0.0082044 | BA42: 0.0083124 | BB42: 0.0084158 | BC42: 0.0085147 | BD42: 0.008594 | BE42: 0.0086696 | BF42: 0.0087424 | BG42: 0.0087974 | BH42: 0.0088535 | BI42: 0.0089152 | BJ42: 0.0089677 | BK42: 0.0090293 | BL42: 0.0091003 | BM42: 0.0091623 | BN42: 0.0092331 | BO42: 0.0093117 | BP42: 0.0093786 | BQ42: 0.0094524 | BR42: 0.0095329 | BS42: 0.0095998 | BT42: 0.0096734 | BU42: 0.0097558 | BV42: 0.0098247 | BW42: 0.0099084 | BX42: 0.0100001 | BY42: 0.0100813 | BZ42: 0.0101731 | CA42: 0.0102756 | CB42: 0.0103681 | CC42: 0.0104706 | CD42: 0.0105828 | CE42: 0.0106838 | CF42: 0.0107901 | CG42: 0.0108998 | CH42: 0.0109917 | CI42: 0.0110842 | CJ42: 0.0111774 | CK42: 0.0112532 | CL42: 0.0113304 | CM42: 0.0114084 | CN42: 0.0114703 | CO42: 0.0115347 | CP42: 0.0116014 | CQ42: 0.0116534 | CR42: 0.0117088 | CS42: 0.0117673 | CT42: 0.0118178 | CU42: 0.0118732 | CV42: 0.0119345 | CW42: 0.0119847 | CX42: 0.0120414 | CY42: 0.0121034 | CZ42: 0.0121527 | DA42: 0.0122067 | DB42: 0.0122647 | DC42: 0.0123087 | DD42: 0.0123573 | DE42: 0.0124128 | DF42: 0.0124575 | DG42: 0.0125127 | DH42: 0.0125778 | DI42: 0.012632 | DJ42: 0.012696 | DK42: 0.0127691 | DL42: 0.0128298 | DM42: 0.0128977 | DN42: 0.0129726 | DO42: 0.0130335 | DP42: 0.0130999 | DQ42: 0.0131726 | DR42: 0.0132306 | DS42: 0.0132943 | DT42: 0.0133639 | DU42: 0.0134192 | DV42: 0.0134805 | DW42: 0.013548 | DX42: 0.013601 | DY42: 0.0136603 | DZ42: 0.013726 | EA42: 0.0137759 | EB42: 0.0138298 | EC42: 0.0138883 | ED42: 0.0139299 | EE42: 0.0139785 | EF42: 0.01403 | EG42: 0.0140659 | EH42: 0.0141069 | EI42: 0.014153 | EJ42: 0.0141824 | EK42: 0.0142159 | EL42: 0.014254 | EM42: 0.0142754 | EN42: 0.0143012 | EO42: 0.0143512 | EP42: 0.0144012 | EQ42: 0.0144512 | ER42: 0.0145012 | ES42: 0.0145512 | ET42: 0.0146012 | EU42: 0.0146512 | EV42: 0.0147012 | EW42: 0.0147512 | EX42: 0.0148012 | EY42: 0.0148512 | EZ42: 0.0149012 | FA42: 0.0149512 | FB42: 0.0150012 | FC42: 0.0150512 | FD42: 0.0151012 | FE42: 0.0151512 | FF42: 0.0152012 | FG42: 0.0152512 | FH42: 0.0153012 | FI42: 0.0153512 | FJ42: 0.0154012 | FK42: 0.0154512 | FL42: 0.0155012 | FM42: 0.0155512 | FN42: 0.0156012 | FO42: 0.0156512 | FP42: 0.0157012 | FQ42: 0.0157512 | FR42: 0.0158012 | FS42: 0.0158512 | FT42: 0.0159012 | FU42: 0.0159512 | FV42: 0.0160012 | FW42: 0.0160512 | FX42: 0.0161012 | FY42: 0.0161512 | FZ42: 0.0162012 | GA42: 0.0162512 | GB42: 0.0163012 | GC42: 0.0163512 | GD42: 0.0164012 | GE42: 0.0164512 | GF42: 0.0165012 | GG42: 0.0165512 | GH42: 0.0166012 | GI42: 0.0166512 | GJ42: 0.0167012 | GK42: 0.0167512 | GL42: 0.0168012 | GM42: 0.0168512
...
